Workbook

Sheet Danh mục vị trí chức danh
A1: CN CTY CP PHÂN BÓN DẦU KHÍ CÀ MAU
A2: XƯỞNG ĐIỀU KHIỂN
A4: DANH MỤC VỊ TRÍ CHỨC DANH
A6: Stt | B6: Chức danh | C6: Phân nhóm | D6: Mã khung năng lực | E6: Điều kiện kèm theo | F6: Ghi chú
A7: 1 | B7: Quản đốc xưởng ĐK | C7: Thuộc danh mục được duyệt | D7: KNL_ĐK_01
A8: 2 | B8: Phó quản đốc xưởng ĐK | C8: Thuộc danh mục được duyệt | D8: KNL_ĐK_02
A9: 3 | B9: Đội trưởng Đội thiết bị đo lường | C9: Thuộc danh mục được duyệt | D9: KNL_ĐK_03
A10: 4 | B10: Đội trưởng Đội thiết bị chấp hành | C10: Thuộc danh mục được duyệt | D10: KNL_ĐK_04
A11: 5 | B11: Đội trưởng Đội thiết bị hệ thống điều khiển | C11: Thuộc danh mục được duyệt | D11: KNL_ĐK_05
A12: 6 | B12: Tổ trưởng tổ trực ca điều khiển | C12: Thuộc danh mục được duyệt | D12: KNL_ĐK_06
A13: 7 | B13: Tổng hợp - X.ĐK, NMĐ | C13: Thuộc danh mục được duyệt | D13: KNL_ĐK_07
A14: 8 | B14: Kỹ sư thiết bị đo lường | C14: Thuộc danh mục được duyệt | D14: KNL_ĐK_08 | F14: Kế hoạch Giữa cuối năm 2026
A15: 9 | B15: Kỹ sư thiết bị hệ thống điều khiển | C15: Thuộc danh mục được duyệt | D15: KNL_ĐK_09 | F15: Kế hoạch Giữa cuối năm 2026
A16: 10 | B16: Kỹ sư BDSC thiết bị hệ thống điều khiển | C16: Thuộc danh mục được duyệt | D16: KNL_ĐK_10 | F16: Kế hoạch Giữa cuối năm 2026
A17: 11 | B17: Kỹ sư thiết bị chấp hành | C17: Thuộc danh mục được duyệt | D17: KNL_ĐK_11 | F17: Kế hoạch Giữa cuối năm 2026
A18: 12 | B18: Kỹ thuật viên trực ca điều khiển | C18: Thuộc danh mục được duyệt | D18: KNL_ĐK_12 | F18: Kế hoạch Giữa đầu năm 2026
A19: 13 | B19: Kỹ thuật viên BDSC thiết bị đo lường | C19: Thuộc danh mục được duyệt | D19: KNL_ĐK_13 | F19: Kế hoạch Giữa đầu năm 2026
A20: 14 | B20: Kỹ thuật viên BDSC thiết bị hệ thống điều khiển | C20: Thuộc danh mục được duyệt | D20: KNL_ĐK_14 | F20: Kế hoạch Giữa đầu năm 2026
A21: 15 | B21: Kỹ thuật viên BDSC thiết bị chấp hành | C21: Thuộc danh mục được duyệt | D21: KNL_ĐK_15 | F21: Kế hoạch Giữa đầu năm 2026
A22: 16 | B22: Tổ trưởng tổ thiết bị Nhiệt độ - độ rung | C22: Kiêm nhiệm | D22: KNL_ĐK_16
A23: 17 | B23: Tổ trưởng tổ thiết bị áp, mức, lưu lượng | C23: Kiêm nhiệm
A24: 18 | B24: Tổ trưởng tổ thiết bị HT điều khiển | C24: Kiêm nhiệm
A25: 19 | B25: Tổ trưởng tổ thiết bị HT phòng cháy | C25: Kiêm nhiệm
A26: 20 | B26: Tổ trưởng tổ thiết bị van ĐK, Junction box | C26: Kiêm nhiệm
A27: 21 | B27: Tổ trưởng tổ TB phân tích | C27: Kiêm nhiệm
A28: 22 | B28: Tổ trưởng tổ TB đóng bao, xuất hàng | C28: Kiêm nhiệm

Sheet Ma trận năng lực
A2: Phân loại | B2: Năng lực chuyên môn | C2: Năng lực chuyên môn chi tiết | D2: Mã năng lực chuyên môn | E2: Định nghĩa (Bắt đầu bằng kiến thức hoặc Kỹ năng hoặc cả 2) | F2: Yêu cầu kiến thức (/Kỹ năng) (nội dung mà người đó cần phải học để đạt được năng lực (sau này là cơ sở lập KH đào tạo nội bộ hoặc bên ngoài) | G2: Mô tả 5 mức điểm năng lực | H2: Hình thức/ cơ sở đánh giá năng lực | I2: Đào tạo nhắc lại (tháng) | J2: Quản đốc xưởng ĐK | K2: Phó quản đốc xưởng ĐK | L2: Đội trưởng Đội thiết bị đo lường | M2: Đội trưởng Đội thiết bị chấp hành | N2: Đội trưởng Đội thiết bị hệ thống điều khiển | O2: Tổ trưởng tổ trực ca điều khiển | P2: Tổng hợp - X.ĐK, NMĐ | Q2: Kỹ sư thiết bị đo lường | R2: Kỹ sư thiết bị hệ thống điều khiển | S2: Kỹ sư BDSC thiết bị hệ thống điều khiển | T2: Kỹ sư thiết bị chấp hành | U2: Kỹ thuật viên trực ca điều khiển | V2: Kỹ thuật viên BDSC thiết bị đo lường | W2: Kỹ thuật viên BDSC thiết bị hệ thống điều khiển | X2: Kỹ thuật viên BDSC thiết bị chấp hành | Y2: Tổ trưởng tổ thiết bị Nhiệt độ - độ rung | Z2: Tổ trưởng tổ thiết bị áp, mức, lưu lượng | AA2: Tổ trưởng tổ thiết bị HT điều khiển | AB2: Tổ trưởng tổ thiết bị HT phòng cháy | AC2: Tổ trưởng tổ thiết bị van ĐK, Junction box | AD2: Tổ trưởng tổ TB phân tích | AE2: Tổ trưởng tổ TB đóng bao, xuất hàng
A3: Số lượng năng lực chuyên môn | J3: =COUNTIF(J4:J120,"x") -> 0 | K3: =COUNTIF(K4:K120,"x") -> 0 | L3: =COUNTIF(L4:L120,"x") -> 0 | M3: =COUNTIF(M4:M120,"x") -> 0 | N3: =COUNTIF(N4:N120,"x") -> 0
A4: Cơ bản | B4: HSE cương vị | C4: An toàn khi làm việc với các thiết bị đo lường tự động hóa | D4: ĐK_NLCM_001 | E4: Kiến thức về an toàn khi làm việc với các thiết bị đo lường tự động hóa | F4: - Nội quy an toàn công ty - Sử dụng PPE phù hợp - Quy trình làm việc an toàn tại khu vực nguy hiểm - Nhận diện mối nguy hiện hữu - An toàn điện | G4: 1 - Không nhận biết nội dung hoặc thuật ngữ chuyên môn/thiếu kiến thức 2 - Có kiến thức nhưng chưa thể làm 3 - Có kiến thức và có thể thực hiện dưới sự giám sát 4 - Có thể thực hiện độc lập 5 - Có thể thực hiện độc lập và có thể dạy lại người khác | H4: Đa phương pháp (Vấn đáp, kiểm tra lý thuyết, thực hành,…) | I4: 6 tháng | S4: x | U4: x | V4: x | W4: x | X4: x
B5: Quy trình làm việc | C5: Quy trình làm việc | D5: ĐK_NLCM_002 | E5: Kiến thức về quy trình làm việc | F5: - Quy trình BDSC (BDĐK & SCĐX) - Quy trình cấp phép làm việc | G5: 1 - Không nhận biết nội dung hoặc thuật ngữ chuyên môn/thiếu kiến thức 2 - Có kiến thức nhưng chưa thể làm 3 - Có kiến thức và có thể thực hiện dưới sự giám sát 4 - Có thể thực hiện độc lập 5 - Có thể thực hiện độc lập và có thể dạy lại người khác | H5: Đa phương pháp (Vấn đáp, kiểm tra lý thuyết, thực hành,…) | S5: x | U5: x | V5: x | W5: x | X5: x
B6: Nhận diện mối nguy và đánh giá rủi ro | C6: =B6 -> Nhận diện mối nguy và đánh giá rủi ro | D6: ĐK_NLCM_003 | E6: Nhận diện mối nguy và đánh giá rủi ro | F6: Phương pháp nhận diện mối nguy, đánh giá rủi ro và biện pháp giảm thiểu | G6: 1 - Không nhận biết nội dung hoặc thuật ngữ chuyên môn/thiếu kiến thức 2 - Có kiến thức nhưng chưa thể làm 3 - Có kiến thức và có thể thực hiện dưới sự giám sát 4 - Có thể thực hiện độc lập 5 - Có thể thực hiện độc lập và có thể dạy lại người khác | H6: Đa phương pháp (Vấn đáp, kiểm tra lý thuyết, thực hành,…) | S6: x | U6: x | V6: x | W6: x | X6: x
B7: Nền tảng chuyên ngành đo lường điều khiển | C7: Điện - Điện tử cơ bản | D7: ĐK_NLCM_004 | E7: Kiến thức Điện - Điện tử cơ bản | F7: - Kiến thức Điện cơ bản + Hiểu các đại lượng: Điện áp, dòng điện, điện trở. + Phân biệt AC/DC + Các khí cụ điện: Relay, khởi động từ, Rờ le nhiệt, Timer cơ bản. - Kiến thức điện tử cơ bản: + Nắm được chức năng, nguyên lý hoạt động của các linh kiện cơ bản như điện trở, tụ điện, cuộn cảm, transistor. + Đại số Boole, hiểu nguyên lý hoạt động của các cổng logic - Kiến thức về tín hiệu: + Phân biệt 2 loại tín hiệu Analog và Digital và mục đích sử dụng 0-10V, 0-5V, 4-20mA + Phân biệt tín hiệu Sink, Source, tín hiệu tín hiệu NO/NC | G7: 1 - Không nhận biết nội dung hoặc thuật ngữ chuyên môn/thiếu kiến thức 2 - Có kiến thức nhưng chưa thể làm 3 - Có kiến thức và có thể thực hiện dưới sự giám sát 4 - Có thể thực hiện độc lập 5 - Có thể thực hiện độc lập và có thể dạy lại người khác | H7: Đa phương pháp (Vấn đáp, kiểm tra lý thuyết, thực hành,…) | I7: 12 tháng | S7: x | U7: x | V7: x | W7: x | X7: x
B8: Nền tảng chuyên ngành đo lường điều khiển | C8: Hệ thống mạng công nghiệp | D8: ĐK_NLCM_005 | E8: Kiến thức và kỹ năng cơ bản về truyền thông công nghiệp | F8: Kiến thức: - Kiến thức nền tảng về truyền thông + Khái niệm: Master – Slave / Client – Server + Tham số truyền thông: Baud rate, Bandwidth - Các chuẩn mạng công nghiệp: + Ethernet: PROFINET, Modbus TCP + Fieldbus: Profibus DP, Modbus RTU, Foundation Fieldbus, HART + Serial: RS232, RS485 - Địa chỉ mạng: + Địa chỉ IP: IPv4, Subnet mask, Gateway + Mac address - Kiến thức phần cứng mạng công nghiệp + Thiết bị mạng: Switch, router, converter. + Cáp & vật tư: Ethernet (CAT5e, CAT6), Cáp quang, Đầu RJ45, ODF, FOC. - Hiểu cơ bản cơ chế trao đổi dữ liệu: OPC, DDE. Kỹ năng: - Thi công / đấu nối đầu RJ45, DP - Hàn cáp quang, kiểm tra suy hao & điểm đứt cáp quang - Lắp đặt/Cấu hình thiết bị mạng (Switch, access point) - Cấu hình đọc dữ liệu từ các giao thức RS232/RS485 TCP/IP. | G8: 1 - Không nhận biết nội dung hoặc thuật ngữ chuyên môn/thiếu kiến thức 2 - Có kiến thức nhưng chưa thể làm 3 - Có kiến thức và có thể thực hiện dưới sự giám sát 4 - Có thể thực hiện độc lập 5 - Có thể thực hiện độc lập và có thể dạy lại người khác | H8: Đa phương pháp (Vấn đáp, kiểm tra lý thuyết, thực hành,…) | I8: 12 tháng | S8: x | W8: x
B9: Nền tảng chuyên ngành đo lường điều khiển | C9: Kiến thức về điều khiển | D9: ĐK_NLCM_006 | E9: Kiến thức về điều khiển | F9: - Khái niệm: Open loop, Closse loop, các thành phần vòng điều khiển, SP, PV, MV. - Đặc tính cơ bản ảnh hưởng đến đáp ứng của process: Process Gain, Time Constant và Dead Time - Bộ điều khiển PID, ảnh hưởng của các thành phần và các chỉ tiêu chất lượng: Overshoot, Settling time, error. | G9: 1 - Không nhận biết nội dung hoặc thuật ngữ chuyên môn/thiếu kiến thức 2 - Có kiến thức nhưng chưa thể làm 3 - Có kiến thức và có thể thực hiện dưới sự giám sát 4 - Có thể thực hiện độc lập 5 - Có thể thực hiện độc lập và có thể dạy lại người khác | H9: Đa phương pháp (Vấn đáp, kiểm tra lý thuyết, thực hành,…) | I9: 12 tháng | S9: x | W9: x
B10: Nền tảng chuyên ngành đo lường điều khiển | C10: Hệ thống máy tính | D10: ĐK_NLCM_007 | E10: Kiến thức và kỹ năng về hệ thống máy tính | F10: Kiến thức: - Nắm được chức năng các phần tử cơ bản: CPU, GPU, RAM, Hard disk, card Raid, card truyền thông, cổng giao tiếp cơ bản, UPS. - Nắm được các loại cấu hình RAID, ưu nhược điểm của từng loại - Nắm cơ bản về an ninh mạng. - Phân biệt IT và OT Kỹ năng: - Quản lý file, thư mục chương trình điều khiển - Cài đặt hệ điều hành - Nắm được các cách Backup và Restore máy tính - Kiểm tra/chuẩn đoán thay thế các phần tử (Ram, Hard disk, card truyền thông,...) - Xử lý lỗi mất kết nối | G10: 1 - Không nhận biết nội dung hoặc thuật ngữ chuyên môn/thiếu kiến thức 2 - Có kiến thức nhưng chưa thể làm 3 - Có kiến thức và có thể thực hiện dưới sự giám sát 4 - Có thể thực hiện độc lập 5 - Có thể thực hiện độc lập và có thể dạy lại người khác | H10: Đa phương pháp (Vấn đáp, kiểm tra lý thuyết, thực hành,…) | I10: 12 tháng | S10: x | W10: x
B11: Nền tảng chuyên ngành đo lường điều khiển | C11: Hệ thống nối đất (grounding system) | D11: ĐK_NLCM_008 | E11: Kiến thức về hệ thống nối đất | F11: - Nguyên lý làm việc của hệ thống. - Các loại nối đất (Nối đất bảo vệ (PE), Nối đất chức năng (FE), Shield Ground), chức năng của từng loại - Kiến trúc hệ thống nối đất (Cọc tiếp địa, dây tiếp địa, thanh cái tiếp địa,…) - Kiến thức về điện trở đất | G11: 1 - Không nhận biết nội dung hoặc thuật ngữ chuyên môn/thiếu kiến thức 2 - Có kiến thức nhưng chưa thể làm 3 - Có kiến thức và có thể thực hiện dưới sự giám sát 4 - Có thể thực hiện độc lập 5 - Có thể thực hiện độc lập và có thể dạy lại người khác | H11: Đa phương pháp (Vấn đáp, kiểm tra lý thuyết, thực hành,…) | I11: 12 tháng | S11: x | W11: x
B12: Công cụ, Dụng cụ cầm tay cho chuyên môn thiết bị HTĐK | C12: =B12 -> Công cụ, Dụng cụ cầm tay cho chuyên môn thiết bị HTĐK | D12: ĐK_NLCM_009 | E12: Kiến thức và kỹ năng sử dụng công cụ dụng cụ cầm tay thuộc chuyên môn thiết bị HTĐK | F12: Kiến thức: Nắm và sử dụng đúng chức năng CCDC Kỹ năng: - Sử dụng công cụ dụng cụ thuộc phạm vi Đội TBHTĐK và Hart communicator - Sử dụng thành thạo dụng cụ điện trong đấu nối và lắp đặt. - Đấu nối cable gland. | G12: 1 - Không nhận biết nội dung hoặc thuật ngữ chuyên môn/thiếu kiến thức 2 - Có kiến thức nhưng chưa thể làm 3 - Có kiến thức và có thể thực hiện dưới sự giám sát 4 - Có thể thực hiện độc lập 5 - Có thể thực hiện độc lập và có thể dạy lại người khác | H12: Đa phương pháp (Vấn đáp, kiểm tra lý thuyết, thực hành,…) | I12: 12 tháng | S12: x | W12: x
B13: P&ID | C13: Kiến thức và kỹ năng về P&ID | D13: ĐK_NLCM_010 | E13: Kiến thức và kỹ năng về P&ID | F13: - Dựa vào P&ID có thể nắm được thông số áp suất, nhiệt độ, môi chất trong đường ống. - Đọc hiểu các ký hiệu trên P&ID (Phân loại tín hiệu, ký hiệu thiết bị đo, phương pháp đo, khối chức năng, điều khiển,...). - Dựa trên P&ID có thể trình bày được chức năng của thiết bị đo, van điều khiển, control loop, Interlock, thiết bị kết nối với hệ thống nào. Kỹ năng: Phát triển và triển khai bản vẽ liên quan đến đo lường điều khiển | G13: 1 - Không nhận biết nội dung hoặc thuật ngữ chuyên môn/thiếu kiến thức 2 - Có kiến thức nhưng chưa thể làm 3 - Có kiến thức và có thể thực hiện dưới sự giám sát 4 - Có thể thực hiện độc lập 5 - Có thể thực hiện độc lập và có thể dạy lại người khác | H13: Đa phương pháp (Vấn đáp, kiểm tra lý thuyết, thực hành,…) | I13: 12 tháng | S13: x | U13: x | V13: x | W13: x | X13: x
B14: IO wiring, Instrument juction box và cable schedule và Interlock | C14: Kiến thức về IO wiring, Instrument juction box và cable schedule, Interlock | D14: ĐK_NLCM_011 | E14: Kiến thức về IO wiring, Instrument juction box và cable schedule, Interlock | F14: Đọc hiểu được các bản vẽ IO wiring, Instrument juction box và cable schedule Đọc hiểu các Interlock cơ bản | G14: 1 - Không nhận biết nội dung hoặc thuật ngữ chuyên môn/thiếu kiến thức 2 - Có kiến thức nhưng chưa thể làm 3 - Có kiến thức và có thể thực hiện dưới sự giám sát 4 - Có thể thực hiện độc lập 5 - Có thể thực hiện độc lập và có thể dạy lại người khác | U14: x | V14: x | X14: x
B15: Công cụ, Dụng cụ cầm tay cho chuyên môn thiết bị Đo lường | C15: =B15 -> Công cụ, Dụng cụ cầm tay cho chuyên môn thiết bị Đo lường | D15: ĐK_NLCM_012 | E15: Kỹ năng sử dụng Công cụ, Dụng cụ cầm tay cho chuyên môn thiết bị Đo lường | F15: Kiến thức: Nắm và sử dụng đúng chức năng CCDC Kỹ năng: - Sử dụng công cụ dụng cụ thuộc phạm vi Đội TBĐL - Đấu nối cable gland. | G15: 1 - Không nhận biết nội dung hoặc thuật ngữ chuyên môn/thiếu kiến thức 2 - Có kiến thức nhưng chưa thể làm 3 - Có kiến thức và có thể thực hiện dưới sự giám sát 4 - Có thể thực hiện độc lập 5 - Có thể thực hiện độc lập và có thể dạy lại người khác | U15: x | V15: x
B16: Công cụ, Dụng cụ cầm tay cho chuyên môn thiết bị van điều khiển | C16: =B16 -> Công cụ, Dụng cụ cầm tay cho chuyên môn thiết bị van điều khiển | D16: ĐK_NLCM_013 | E16: Kỹ năng sử dụng Công cụ, Dụng cụ cầm tay cho chuyên môn thiết bị van điều khiển | F16: Kiến thức: Nắm và sử dụng đúng chức năng CCDC Kỹ năng: - Sử dụng công cụ dụng cụ thuộc phạm vi Đội TBCH - Sử dụng thành thạo dụng cụ điện trong đấu nối và lắp đặt. - Đấu nối cable gland. | G16: 1 - Không nhận biết nội dung hoặc thuật ngữ chuyên môn/thiếu kiến thức 2 - Có kiến thức nhưng chưa thể làm 3 - Có kiến thức và có thể thực hiện dưới sự giám sát 4 - Có thể thực hiện độc lập 5 - Có thể thực hiện độc lập và có thể dạy lại người khác | U16: x | X16: x
B17: Vật lý cơ bản | C17: Kiến thức về vật lý và đại lượng đo lường cơ bản | D17: ĐK_NLCM_014 | E17: Kiến thức về vật lý và đại lượng đo lường cơ bản | F17: - Định nghĩa áp suất, lưu lượng, nhiệt độ, độ rung. - Phân biệt áp suất tương đối, áp suất tuyệt đối - Định nghĩa Cột áp thủy tỉnh - Định nghĩa Zero value, calibration range, Span và Instrument range - Định nghĩa Độ chính xác (Accuracy), độ lặp lại (Precision), độ phân giải (Resolution), tuyến tính (Linearity), độ trễ (Hysteresis) - Các định luật: Ohm, Kirchhoff, Faraday, Bernoulli, Seebeck, Pascal. - Hiện tượng vật lý: Ngưng tụ (condensation), bay hơi. | G17: 1 - Không nhận biết nội dung hoặc thuật ngữ chuyên môn/thiếu kiến thức 2 - Có kiến thức nhưng chưa thể làm 3 - Có kiến thức và có thể thực hiện dưới sự giám sát 4 - Có thể thực hiện độc lập 5 - Có thể thực hiện độc lập và có thể dạy lại người khác | U17: x | V17: x | X17: x
B18: Lựa chọn fitting, tubing | C18: =B18 -> Lựa chọn fitting, tubing | D18: ĐK_NLCM_015 | E18: Kiến thức và kỹ năng liên quan đến lựa chọn fitting và tubing | F18: Kiến thức: - Nắm vững các loại fitting và tubing tại NM ĐCM. - Tuân thủ các nguyên tắc, lựa chọn đúng kích thước tubing và fitting. (không sử dụng lẫn ferrule giữa các hãng khác nhau) Kỹ năng: - Lắp đặt và uống ống Impluse line | G18: 1 - Không nhận biết nội dung hoặc thuật ngữ chuyên môn/thiếu kiến thức 2 - Có kiến thức nhưng chưa thể làm 3 - Có kiến thức và có thể thực hiện dưới sự giám sát 4 - Có thể thực hiện độc lập 5 - Có thể thực hiện độc lập và có thể dạy lại người khác | U18: x | V18: x | X18: x
B19: Công nghệ sản xuất | C19: Hiểu cơ bản về công nghệ sản xuất trong Nhà máy | D19: ĐK_NLCM_016 | E19: Kiến thức cơ bản về quy trình công nghệ sản xuất tại Nhà máy Đạm Cà Mau từ khí đầu vào đến tạo hạt, đóng bao. | F19: - Nắm tổng quan các phân Xưởng trong NM ĐCM: chức năng và vai trò. - Lưu đồ công nghệ về phân cụm: chức năng và vai trò. | G19: 1 - Không nhận biết nội dung hoặc thuật ngữ chuyên môn/thiếu kiến thức 2 - Có kiến thức nhưng chưa thể làm 3 - Có kiến thức và có thể thực hiện dưới sự giám sát 4 - Có thể thực hiện độc lập 5 - Có thể thực hiện độc lập và có thể dạy lại người khác | H19: Đa phương pháp (Vấn đáp, kiểm tra lý thuyết, thực hành,…) | I19: 12 tháng | S19: x | U19: x | V19: x | W19: x | X19: x
B20: Tổng quan Hệ thống điều khiển nhà máy Đạm Cà Mau | C20: Nắm được chức năng của tất cả hệ thống điều khiển tại nhà máy Đạm Cà Mau | D20: ĐK_NLCM_017 | E20: Nắm được chức năng của các hệ thống điều khiển tại nhà máy Đạm Cà Mau bao gồm Hệ thống điều khiển phân tán, ESD, hệ thống điều khiển Turbine và máy nén, hệ thống MPS/MMS, hệ thống đóng bao xuất hàng | F20: - Nắm tổng quan Hệ thống điều khiển tại NM ĐCM: chức năng và vai trò của các hệ thống - Sự kết nối giữa các hệ thống, phương thức kết nối. | G20: 1 - Không nhận biết nội dung hoặc thuật ngữ chuyên môn/thiếu kiến thức 2 - Có kiến thức nhưng chưa thể làm 3 - Có kiến thức và có thể thực hiện dưới sự giám sát 4 - Có thể thực hiện độc lập 5 - Có thể thực hiện độc lập và có thể dạy lại người khác | H20: Đa phương pháp (Vấn đáp, kiểm tra lý thuyết, thực hành,…) | I20: 12 tháng | S20: x | U20: x | V20: x | W20: x | X20: x
B21: Tổng quan Thiết bị đo lường và van điều khiển nhà máy Đạm Cà Mau | C21: Kiến thức về thiết bị đo lường và van điều khiển tại nhà máy Đạm Cà Mau | D21: ĐK_NLCM_018 | E21: Kiến thức về thiết bị đo lường và van điều khiển tại nhà máy Đạm Cà Mau | F21: - Biết được các thiết bị đo: Mức, áp, lưu lượng, nhiệt độ, đầu dò độ rung đang áp dụng tại NM ĐCM. - Biết được các loại van điều khiển đang được sử dụng tại NM ĐCM | G21: 1 - Không nhận biết nội dung hoặc thuật ngữ chuyên môn/thiếu kiến thức 2 - Có kiến thức nhưng chưa thể làm 3 - Có kiến thức và có thể thực hiện dưới sự giám sát 4 - Có thể thực hiện độc lập 5 - Có thể thực hiện độc lập và có thể dạy lại người khác | H21: Đa phương pháp (Vấn đáp, kiểm tra lý thuyết, thực hành,…) | I21: 12 tháng | S21: x | U21: x | V21: x | W21: x | X21: x
B22: Kiến thức tổng quan về biện pháp phòng nổ (Ex protection) | C22: Vùng nguy hiểm (Hazardous Areas) | D22: ĐK_NLCM_019 | E22: Kiến thức về vùng nguy hiểm | F22: - Khái niệm vùng nguy hiểm theo ATEX/IECEx, phân vùng nguy hiểm trong NM ĐCM. - Hiểu nguyên lý cháy nổ (tam giác cháy) | G22: 1 - Không nhận biết nội dung hoặc thuật ngữ chuyên môn/thiếu kiến thức 2 - Có kiến thức nhưng chưa thể làm 3 - Có kiến thức và có thể thực hiện dưới sự giám sát 4 - Có thể thực hiện độc lập 5 - Có thể thực hiện độc lập và có thể dạy lại người khác | H22: Đa phương pháp (Vấn đáp, kiểm tra lý thuyết, thực hành,…) | I22: 12 tháng | S22: x | U22: x | V22: x | W22: x | X22: x
B23: Kiến thức tổng quan về biện pháp phòng nổ (Ex protection) | C23: Đọc và hiểu ký hiệu Ex trên thiết bị | D23: ĐK_NLCM_020 | E23: Kiến thức về ký hiệu phòng nổ trên thiết bị | F23: - Các phương pháp phòng nổ tại nhà máy Đạm Cà Mau - Sử dụng công cụ/tài liệu để đọc được Ex marking trên thiết bị | G23: 1 - Không nhận biết nội dung hoặc thuật ngữ chuyên môn/thiếu kiến thức 2 - Có kiến thức nhưng chưa thể làm 3 - Có kiến thức và có thể thực hiện dưới sự giám sát 4 - Có thể thực hiện độc lập 5 - Có thể thực hiện độc lập và có thể dạy lại người khác | H23: Đa phương pháp (Vấn đáp, kiểm tra lý thuyết, thực hành,…) | I23: 12 tháng | S23: x | U23: x | V23: x | W23: x | X23: x
B24: Kỹ năng mềm chuyên ngành Đo lường - Điều khiển | C24: =B24 -> Kỹ năng mềm chuyên ngành Đo lường - Điều khiển | D24: ĐK_NLCM_021 | E24: Kỹ năng mềm chuyên ngành Đo lường - Điều khiển | F24: - Sử dụng được phần mềm Autocad - Kỹ năng soạn thảo Email - Kỹ năng soạn thảo báo cáo (Excel, Word, PowerPoint, Visio, Ms project) | G24: 1 - Không nhận biết nội dung hoặc thuật ngữ chuyên môn/thiếu kiến thức 2 - Có kiến thức nhưng chưa thể làm 3 - Có kiến thức và có thể thực hiện dưới sự giám sát 4 - Có thể thực hiện độc lập 5 - Có thể thực hiện độc lập và có thể dạy lại người khác | H24: - Hỏi - đáp - Kiểm tra lý thuyết (trắc nghiệm/viết ngắn) | I24: 12 tháng | S24: x
B25: Nắm được nguyên lý hoạt động Turbine/máy nén và nồi hơi | C25: Nắm được nguyên lý hoạt động Turbine/máy nén và nồi hơi | D25: ĐK_NLCM_022 | E25: Nắm được nguyên lý hoạt động Turbine/máy nén và nồi hơi | F25: Nắm được nguyên lý hoạt động Turbine/máy nén và nồi hơi … | G25: 1 - Không nhận biết nội dung hoặc thuật ngữ chuyên môn/thiếu kiến thức 2 - Có kiến thức nhưng chưa thể làm 3 - Có kiến thức và có thể thực hiện dưới sự giám sát 4 - Có thể thực hiện độc lập 5 - Có thể thực hiện độc lập và có thể dạy lại người khác | S25: x
B26: Kiến thức và kỹ năng liên quan đến hệ thống các tiêu chuẩn Quốc tế liên quan đến ngành đo lường điều khiển | C26: =B26 -> Kiến thức và kỹ năng liên quan đến hệ thống các tiêu chuẩn Quốc tế liên quan đến ngành đo lường điều khiển | D26: ĐK_NLCM_023 | E26: =C26 -> Kiến thức và kỹ năng liên quan đến hệ thống các tiêu chuẩn Quốc tế liên quan đến ngành đo lường điều khiển | F26: - IEC – nền tảng của ngành Đo lường Điều khiển: IEC 61511, IEC 60079 - API 554 Process Instrumentation and Control, API 612: turbine, compressor Kỹ năng: - Có thể đọc hiểu, áp dụng các tiêu chuẩn vào thực tế công việc | G26: 1 - Không nhận biết nội dung hoặc thuật ngữ chuyên môn/thiếu kiến thức 2 - Có kiến thức nhưng chưa thể làm 3 - Có kiến thức và có thể thực hiện dưới sự giám sát 4 - Có thể thực hiện độc lập 5 - Có thể thực hiện độc lập và có thể dạy lại người khác | S26: x
B27: Trí tuệ nhân tạo (AI) | C27: Trí tuệ nhân tạo (AI) | D27: ĐK_NLCM_024 | E27: Kiến thức và kỹ năng liên về trí tuệ nhân tạo (AI) | F27: Kiến thức - Nắm được nguyên tắc hoạt động cơ bản của các công cụ AI hỗ trợ xử lý thông tin, phân tích dữ liệu và tạo nội dung. - Hiểu các giới hạn và rủi ro khi sử dụng AI, bao gồm độ chính xác thông tin và bảo mật dữ liệu. - Nhận biết các ứng dụng AI phổ biến trong công việc văn phòng và kỹ thuật như hỗ trợ viết báo cáo, phân tích dữ liệu, tra cứu tài liệu kỹ thuật. Kỹ năng: - Sử dụng các công cụ AI để hỗ trợ tìm kiếm, tổng hợp và phân tích thông tin phục vụ công việc. - Ứng dụng AI trong soạn thảo tài liệu kỹ thuật, báo cáo và trình bày nội dung. - Biết đặt câu hỏi (prompt) rõ ràng để khai thác hiệu quả thông tin từ công cụ AI. - Kiểm tra, đánh giá và xác minh lại kết quả do AI cung cấp trước khi áp dụng vào thực tế. - Kết hợp AI với các công cụ làm việc khác (Excel, tài liệu kỹ thuật, hệ thống quản lý dữ liệu) để nâng cao hiệu quả công việc. | G27: 1 - Không nhận biết nội dung hoặc thuật ngữ chuyên môn/thiếu kiến thức 2 - Có kiến thức nhưng chưa thể làm 3 - Có kiến thức và có thể thực hiện dưới sự giám sát 4 - Có thể thực hiện độc lập 5 - Có thể thực hiện độc lập và có thể dạy lại người khác | H27: Đa phương pháp (Vấn đáp, kiểm tra lý thuyết, thực hành,…) | S27: x | U27: x | V27: x | W27: x | X27: x
B28: Hệ thống Fire Alarm- FA & Automatic Fire Fighting System- AFFS | C28: Hệ thống FA & AFFS | D28: ĐK_NLCM_025 | E28: Kiến thức và kỹ năng liên quan đến hệ thống FA & AFFS | F28: Kiến thức: - Hệ thống báo cháy: FA + Nguyên lý Đầu báo khói - nhiệt được sử dụng trong NM ĐCM + Chức năng nút nhấn khẩn (Manual Call Point) + Điều khiển chuông, còi, đèn, relay + Bản vẽ đấu nối thiết bị, kết nối với hệ thống AFFS & Fire and Gas - Hệ thống chữa cháy tự động (AFFS): FM-200, CO2, Bọt Foam. + Chức năng hệ thống + Bản vẽ đấu nối thiết bị, kết nối với hệ thống FA - Tiêu chuẩn + TCVN 3890 Trang bị, kiểm tra hệ thống báo cháy – chữa cháy + TCVN 5760/5738 Hệ thống báo cháy tự động – thiết kế & lắp đặt Kỹ năng: - Đấu nối dây loop & end-of-line (EOL) - Sử dụng cơ bản phần mềm Notifier Verifire Tool (Cấu hình khai báo mới, relay, còi, đèn, chuông, thiết lập Interlock, MOC) - Sử dụng công cụ để backup/restore hệ thống | G28: 1 - Không nhận biết nội dung hoặc thuật ngữ chuyên môn/thiếu kiến thức 2 - Có kiến thức nhưng chưa thể làm 3 - Có kiến thức và có thể thực hiện dưới sự giám sát 4 - Có thể thực hiện độc lập 5 - Có thể thực hiện độc lập và có thể dạy lại người khác | H28: Đa phương pháp (Vấn đáp, kiểm tra lý thuyết, thực hành,…) | I28: 12 tháng | S28: x | W28: x
B29: Phần cứng hệ thống MPS/MMS | C29: Phần cứng hệ thống MPS/MMS | D29: ĐK_NLCM_026 | E29: Kiến trúc phần cứng hệ thống MPS/MMS | F29: Kiến thức nền tảng: - Nắm được kiến trúc phần cứng: liệt kê các phần tử, nêu được chức năng từng phần tử - Đọc hiểu bản vẽ IO wiring, trình bày được đường đi của tín hiệu từ thiết bị hiện trường đến Card và ngược lại. - Nắm được chức năng từng loại card. Kỹ năng: - Có thể lắp đặt, đấu nối tín hiệu, thay thế các phần tử trong hệ thống. | G29: 1 - Không nhận biết nội dung hoặc thuật ngữ chuyên môn/thiếu kiến thức 2 - Có kiến thức nhưng chưa thể làm 3 - Có kiến thức và có thể thực hiện dưới sự giám sát 4 - Có thể thực hiện độc lập 5 - Có thể thực hiện độc lập và có thể dạy lại người khác | H29: Đa phương pháp (Vấn đáp, kiểm tra lý thuyết, thực hành,…) | I29: 12 tháng | S29: x | W29: x
B30: Phần mềm hệ thống MPS/MMS | C30: Phần mềm hệ thống MPS/MMS | D30: ĐK_NLCM_027 | E30: Kiến trúc phần mềm hệ thống MPS/MMS | F30: Kiến thức: - Nắm được các loại tín hiệu giám sát máy động. - Nắm được kiến trúc phần mềm: nắm được các câu lệnh cấu hình trong Rack 3500. - Đọc hiểu bản vẽ Interlock và trình bày được sự hiện diện bên trong chương trình. - Nắm được phương thức kết nối/logic tác động với các hệ thống khác. Kỹ năng - Sử dụng cơ bản phần mềm Rack 3500, System1 (Có thể cấu hình mới, MOC, Backup / Restore Configuration) - Sử dụng công cụ cầm tay để mô phỏng và đo đạc tín hiệu độ rung (CA150, Fluke744, oscilloscope) | G30: 1 - Không nhận biết nội dung hoặc thuật ngữ chuyên môn/thiếu kiến thức 2 - Có kiến thức nhưng chưa thể làm 3 - Có kiến thức và có thể thực hiện dưới sự giám sát 4 - Có thể thực hiện độc lập 5 - Có thể thực hiện độc lập và có thể dạy lại người khác | H30: Đa phương pháp (Vấn đáp, kiểm tra lý thuyết, thực hành,…) | I30: 12 tháng | S30: x | W30: x
B31: Phần cứng hệ thống DCS | C31: Phần cứng hệ thống DCS | D31: ĐK_NLCM_028 | E31: Kiến thức và kỹ năng liên quan đến phần cứng hệ thống DCS | F31: Kiến thức: - Nắm được kiến trúc phần cứng hệ thống DCS nhà máy Đạm Cà Mau, liệt kê các phần tử có trong SYS & Marshalling Cabinet, HIS nêu được chức năng từng phần tử - Mạng truyền thông hệ thống DCS - Đọc hiểu bản vẽ IO wiring, trình bày được đường đi của tín hiệu từ thiết bị hiện trường đến Card và ngược lại. - Nắm được chức năng từng loại card và các phần tử phụ trợ Kỹ năng: - Có thể lắp đặt, thay thế các phần tử trong hệ thống. - Có khả năng cấu hình phần cứng | G31: 1 - Không nhận biết nội dung hoặc thuật ngữ chuyên môn/thiếu kiến thức 2 - Có kiến thức nhưng chưa thể làm 3 - Có kiến thức và có thể thực hiện dưới sự giám sát 4 - Có thể thực hiện độc lập 5 - Có thể thực hiện độc lập và có thể dạy lại người khác | H31: Đa phương pháp (Vấn đáp, kiểm tra lý thuyết, thực hành,…) | I31: 12 tháng | S31: x | W31: x
B32: Phần mềm hệ thống DCS | C32: Phần mềm hệ thống DCS | D32: ĐK_NLCM_029 | E32: Kiến thức và kỹ năng liên quan đến phần mềm hệ thống DCS | F32: Kiến thức: - Nắm được kiến trúc phần mềm: hiểu các khối cơ bản có trong project nhà máy Đạm Cà Mau, cách thức tổ chức chương trình. - Nắm được các chuẩn truyền thông. - Đọc hiểu bản vẽ Interlock, instrument loop diagram. - Tích hợp hệ thống: Nắm được phương thức kết nối/logic tác động với các hệ thống khác Kỹ năng: - Sử dụng cơ bản phần mềm System view (Project Creation/Attribution Utility Project Common Definition, FCS Configuration, I/O Module Configuration Software Switches Configuration Message Configuration, Control Drawing Builder, HIS Configuration, Window Configuration, Graphic Builder, Diagnotic kiểm tra trạng thái: IO card, FCU, truyền thông) | G32: 1 - Không nhận biết nội dung hoặc thuật ngữ chuyên môn/thiếu kiến thức 2 - Có kiến thức nhưng chưa thể làm 3 - Có kiến thức và có thể thực hiện dưới sự giám sát 4 - Có thể thực hiện độc lập 5 - Có thể thực hiện độc lập và có thể dạy lại người khác | H32: Đa phương pháp (Vấn đáp, kiểm tra lý thuyết, thực hành,…) | I32: 12 tháng | S32: x | W32: x
B33: Phần cứng hệ thống F&G | C33: Phần cứng hệ thống F&G | D33: ĐK_NLCM_030 | E33: Kiến trúc phần cứng hệ thống F&G | F33: Kiến thức: - Nắm được kiến trúc phần cứng: liệt kê các phần tử, nêu được chức năng từng phần tử - Đọc hiểu bản vẽ IO wiring, trình bày được đường đi của tín hiệu từ thiết bị hiện trường đến Card và ngược lại. - Nắm được chức năng từng loại card và các phần tử phụ trợ Kỹ năng: - Có thể lắp đặt, thay thế các phần tử trong hệ thống. | G33: 1 - Không nhận biết nội dung hoặc thuật ngữ chuyên môn/thiếu kiến thức 2 - Có kiến thức nhưng chưa thể làm 3 - Có kiến thức và có thể thực hiện dưới sự giám sát 4 - Có thể thực hiện độc lập 5 - Có thể thực hiện độc lập và có thể dạy lại người khác | H33: Đa phương pháp (Vấn đáp, kiểm tra lý thuyết, thực hành,…) | I33: 12 tháng | S33: x | W33: x
B34: Phần mềm hệ thống F&G | C34: Phần mềm hệ thống F&G | D34: ĐK_NLCM_031 | E34: Kiến trúc phần mềm hệ thống F&G | F34: Kiến thức: - Nắm được kiến trúc phần mềm: hiểu chức năng các khối cấu hình trong project nhà máy Đạm Cà Mau. - Đọc hiểu bản vẽ IO wiring và trình bày được sự hiện diện bên trong chương trình - Nắm được các chuẩn truyền thông - Nắm được phương thức kết nối/logic tác động với các hệ thống khác Kỹ năng - Sử dụng cơ bản phần mềm TriStation, Intouch WindowMarker | G34: 1 - Không nhận biết nội dung hoặc thuật ngữ chuyên môn/thiếu kiến thức 2 - Có kiến thức nhưng chưa thể làm 3 - Có kiến thức và có thể thực hiện dưới sự giám sát 4 - Có thể thực hiện độc lập 5 - Có thể thực hiện độc lập và có thể dạy lại người khác | H34: Đa phương pháp (Vấn đáp, kiểm tra lý thuyết, thực hành,…) | I34: 12 tháng | S34: x | W34: x
B35: Phần cứng hệ thống ESD | C35: Phần cứng hệ thống ESD | D35: ĐK_NLCM_032 | E35: Kiến trúc phần cứng hệ thống ESD | F35: Kiến thức: - Nắm được kiến trúc phần cứng: liệt kê các phần tử, nêu được chức năng từng phần tử - Đọc hiểu bản vẽ IO wiring, trình bày được đường đi của tín hiệu từ thiết bị hiện trường đến Card và ngược lại. - Nắm được chức năng từng loại card và các phần tử phụ trợ Kỹ năng: - Có thể lắp đặt, thay thế các phần tử trong hệ thống. | G35: 1 - Không nhận biết nội dung hoặc thuật ngữ chuyên môn/thiếu kiến thức 2 - Có kiến thức nhưng chưa thể làm 3 - Có kiến thức và có thể thực hiện dưới sự giám sát 4 - Có thể thực hiện độc lập 5 - Có thể thực hiện độc lập và có thể dạy lại người khác | H35: Đa phương pháp (Vấn đáp, kiểm tra lý thuyết, thực hành,…) | I35: 12 tháng | S35: x | W35: x
B36: Phần mềm hệ thống ESD | C36: Phần mềm hệ thống ESD | D36: ĐK_NLCM_033 | E36: Kiến trúc phần mềm hệ thống ESD | F36: Kiến thức: - Nắm được kiến trúc phần mềm, lập trình trên Tristation, hiểu chức năng các khối cấu hình trong project nhà máy Đạm Cà Mau. - Đọc hiểu Cause & Effect của nhà máy Đạm Cà Mau - Đọc hiểu bản vẽ Interlock - Nắm được các chuẩn truyền thông - Tích hợp hệ thống: Nắm được phương thức kết nối/logic tác động với các hệ thống khác Kỹ năng - Sử dụng cơ bản phần mềm TriStation, Intouch WindowMarker, SOE. - Force, bypass, MOS các tín hiệu | G36: 1 - Không nhận biết nội dung hoặc thuật ngữ chuyên môn/thiếu kiến thức 2 - Có kiến thức nhưng chưa thể làm 3 - Có kiến thức và có thể thực hiện dưới sự giám sát 4 - Có thể thực hiện độc lập 5 - Có thể thực hiện độc lập và có thể dạy lại người khác | H36: Đa phương pháp (Vấn đáp, kiểm tra lý thuyết, thực hành,…) | I36: 12 tháng | S36: x | W36: x
B37: Phần cứng hệ thống PLC | C37: Phần cứng hệ thống PLC | D37: ĐK_NLCM_034 | E37: Kiến thức và kỹ năng liên quan đến phần cứng hệ thống PLC | F37: Kiến thức: - Nắm được kiến trúc phần cứng: liệt kê các phần tử có trong SYS & Marshalling Cabinet, nêu được chức năng từng phần tử. - Đọc hiểu bản vẽ wiring, trình bày được đường đi của tín hiệu từ thiết bị hiện trường đến Card và ngược lại. - Nắm được chức năng từng loại card và các phần tử phụ trợ Kỹ năng: - Có thể lắp đặt, thay thế các phần tử trong hệ thống. | G37: 1 - Không nhận biết nội dung hoặc thuật ngữ chuyên môn/thiếu kiến thức 2 - Có kiến thức nhưng chưa thể làm 3 - Có kiến thức và có thể thực hiện dưới sự giám sát 4 - Có thể thực hiện độc lập 5 - Có thể thực hiện độc lập và có thể dạy lại người khác | H37: Đa phương pháp (Vấn đáp, kiểm tra lý thuyết, thực hành,…) | I37: 12 tháng | S37: x | W37: x
B38: Phần mềm hệ thống PLC | C38: Phần mềm hệ thống PLC | D38: ĐK_NLCM_035 | E38: Kiến trúc và kỹ năng liên quan đến phần mềm hệ thống PLC | F38: Kiến thức: - Khái niệm về: Biến và kiểu dữ liệu, address và indirect address, Cycle time, software/hardware interupt. - Nắm được kiến trúc phần mềm: Cách tổ chức chương trình Simens và Allen-Bradley. - Đọc hiểu được chương trình (Ngôn ngữ ladder, FBD và CFC) - Nắm được các chuẩn truyền thông trong nội tại hệ thống PLC - Tích hợp hệ thống: Nắm được phương thức kết nối/logic tác động với các hệ thống khác Kỹ năng: - Backup, restore chương trình/HMI - Force, Bypass, MOS và simulate tín hiệu | G38: 1 - Không nhận biết nội dung hoặc thuật ngữ chuyên môn/thiếu kiến thức 2 - Có kiến thức nhưng chưa thể làm 3 - Có kiến thức và có thể thực hiện dưới sự giám sát 4 - Có thể thực hiện độc lập 5 - Có thể thực hiện độc lập và có thể dạy lại người khác | H38: Đa phương pháp (Vấn đáp, kiểm tra lý thuyết, thực hành,…) | S38: x | W38: x
B39: Hệ thống PLC nâng cao | C39: =B39 -> Hệ thống PLC nâng cao | D39: ĐK_NLCM_036 | E39: Kiến trúc và kỹ năng nâng cao liên quan đến hệ thống PLC | F39: Kiến thức: - Đọc hiểu được chương trình (Ngôn ngữ STL, SCL) - Nắm được các loop/logic điều khiển các hệ thống turbine/máy nén KT04421/K04421, KT04441/K04441, KT04431/K04431, KT06101/K06101 và BMS - Liên kết được hướng dẫn vận hành (Điều kiện công nghệ) với logic điều khiển Kỹ năng: - Thành thạo môi trường engineering (Simatic, TriStation) - Phân tích root cause (RCA) sự cố hệ thống điều khiển | G39: 1 - Không nhận biết nội dung hoặc thuật ngữ chuyên môn/thiếu kiến thức 2 - Có kiến thức nhưng chưa thể làm 3 - Có kiến thức và có thể thực hiện dưới sự giám sát 4 - Có thể thực hiện độc lập 5 - Có thể thực hiện độc lập và có thể dạy lại người khác | S39: x
B40: Hệ thống DCS nâng cao | C40: =B40 -> Hệ thống DCS nâng cao | D40: ĐK_NLCM_037 | E40: Kiến thức và kỹ năng chuyên sâu liên quan đến hệ thống DCS | F40: Kiến thức: - Thiết kế control logic phức tạp (interlock, permissive, trip) - Bảo mật cho hệ thống DCS Kỹ năng: - Thành thạo môi trường engineering (System view) - Phân tích root cause (RCA) sự cố hệ thống điều khiển | G40: 1 - Không nhận biết nội dung hoặc thuật ngữ chuyên môn/thiếu kiến thức 2 - Có kiến thức nhưng chưa thể làm 3 - Có kiến thức và có thể thực hiện dưới sự giám sát 4 - Có thể thực hiện độc lập 5 - Có thể thực hiện độc lập và có thể dạy lại người khác | S40: x
B41: Hệ thống ESD nâng cao | C41: =B41 -> Hệ thống ESD nâng cao | D41: ĐK_NLCM_038 | E41: Kiến thức và kỹ năng chuyên sâu liên quan đến hệ thống ESD | F41: Kiến thức: - Nắm được Cause & Effect của nhà máy Đạm Cà Mau - Nắm rõ các Safety Interlock tại nhà máy Đạm Cà Mau - Bảo mật cho hệ thống ESD Kỹ năng: - Thành thạo môi trường engineering (TriStation, Intouch WindowMarker, SOE) - Phân tích root cause (RCA) sự cố hệ thống điều khiển | G41: 1 - Không nhận biết nội dung hoặc thuật ngữ chuyên môn/thiếu kiến thức 2 - Có kiến thức nhưng chưa thể làm 3 - Có kiến thức và có thể thực hiện dưới sự giám sát 4 - Có thể thực hiện độc lập 5 - Có thể thực hiện độc lập và có thể dạy lại người khác | S41: x
...

Sheet KNL_ĐK_10
A1: KHUNG NĂNG LỰC CHUYÊN MÔN
A2: Kỹ sư BDSC thiết bị hệ thống điều khiển (KNL_ĐK_10)
A3: Phân nhóm | B3: Năng lực chuyên môn | C3: Stt | D3: Mã năng lực | E3: Chi tiết năng lực chuyên môn | F3: Bậc 1 | G3: Bậc 2 | H3: Bậc 3 | I3: Bậc 4 | J3: Bậc 5 | K3: Bậc 6 | L3: Bậc 7 | M3: Bậc 8
F4: =SUM(F6:F55) -> 51 | G4: =SUM(G6:G55) -> 108 | H4: =SUM(H6:H55) -> 130 | I4: =SUM(I6:I55) -> 136 | J4: =SUM(J6:J55) -> 136 | K4: =SUM(K6:K55) -> 145 | L4: =SUM(L6:L55) -> 161 | M4: =SUM(M6:M55) -> 178
F5: 1 | G5: 2 | H5: 3 | I5: 4 | J5: 5 | K5: 6 | L5: 7 | M5: 8
A6: Cơ bản | B6: =INDEX('Ma trận năng lực'!B:B, MATCH(D6, 'Ma trận năng lực'!D:D, 0)) -> HSE cương vị | C6: =ROW()-5 -> 1 | D6: {=_xlfn._xlws.FILTER('Ma trận năng lực'!D:D,'Ma trận năng lực'!S:S="x")} -> ĐK_NLCM_001 | E6: =VLOOKUP(D6,'Ma trận năng lực'!D4:E69,2,1) -> Kiến thức về an toàn khi làm việc với các thiết bị đo lường tự động hóa | F6: 1 | G6: 4 | H6: 4 | I6: 4 | J6: 4 | K6: 4 | L6: 5 | M6: 5
B7: =INDEX('Ma trận năng lực'!B:B, MATCH(D7, 'Ma trận năng lực'!D:D, 0)) -> Quy trình làm việc | C7: =ROW()-5 -> 2 | D7: ĐK_NLCM_002 | E7: =VLOOKUP(D7,'Ma trận năng lực'!D5:E70,2,1) -> Kiến thức về quy trình làm việc | F7: 1 | G7: 4 | H7: 4 | I7: 4 | J7: 4 | K7: 4 | L7: 5 | M7: 5
B8: =INDEX('Ma trận năng lực'!B:B, MATCH(D8, 'Ma trận năng lực'!D:D, 0)) -> Nhận diện mối nguy và đánh giá rủi ro | C8: =ROW()-5 -> 3 | D8: ĐK_NLCM_003 | E8: =VLOOKUP(D8,'Ma trận năng lực'!D6:E71,2,1) -> Nhận diện mối nguy và đánh giá rủi ro | F8: 1 | G8: 4 | H8: 2 | I8: 2 | J8: 2 | K8: 2 | L8: 2 | M8: 2
B9: =INDEX('Ma trận năng lực'!B:B, MATCH(D9, 'Ma trận năng lực'!D:D, 0)) -> Nền tảng chuyên ngành đo lường điều khiển | C9: =ROW()-5 -> 4 | D9: ĐK_NLCM_004 | E9: =VLOOKUP(D9,'Ma trận năng lực'!D7:E72,2,1) -> Kiến thức Điện - Điện tử cơ bản | F9: 2 | G9: 2 | H9: 4 | I9: 4 | J9: 4 | K9: 4 | L9: 5 | M9: 5
B10: =INDEX('Ma trận năng lực'!B:B, MATCH(D10, 'Ma trận năng lực'!D:D, 0)) -> Nền tảng chuyên ngành đo lường điều khiển | C10: =ROW()-5 -> 5 | D10: ĐK_NLCM_005 | E10: =VLOOKUP(D10,'Ma trận năng lực'!D8:E73,2,1) -> Kiến thức và kỹ năng cơ bản về truyền thông công nghiệp | F10: 2 | G10: 4 | H10: 2 | I10: 2 | J10: 2 | K10: 2 | L10: 2 | M10: 2
B11: =INDEX('Ma trận năng lực'!B:B, MATCH(D11, 'Ma trận năng lực'!D:D, 0)) -> Nền tảng chuyên ngành đo lường điều khiển | C11: =ROW()-5 -> 6 | D11: ĐK_NLCM_006 | E11: =VLOOKUP(D11,'Ma trận năng lực'!D9:E74,2,1) -> Kiến thức về điều khiển | F11: 2 | G11: 2 | H11: 4 | I11: 4 | J11: 4 | K11: 4 | L11: 5 | M11: 5
B12: =INDEX('Ma trận năng lực'!B:B, MATCH(D12, 'Ma trận năng lực'!D:D, 0)) -> Nền tảng chuyên ngành đo lường điều khiển | C12: =ROW()-5 -> 7 | D12: ĐK_NLCM_007 | E12: =VLOOKUP(D12,'Ma trận năng lực'!D10:E75,2,1) -> Kiến thức và kỹ năng về hệ thống máy tính | F12: 2 | G12: 4 | H12: 2 | I12: 2 | J12: 2 | K12: 2 | L12: 2 | M12: 2
B13: =INDEX('Ma trận năng lực'!B:B, MATCH(D13, 'Ma trận năng lực'!D:D, 0)) -> Nền tảng chuyên ngành đo lường điều khiển | C13: =ROW()-5 -> 8 | D13: ĐK_NLCM_008 | E13: =VLOOKUP(D13,'Ma trận năng lực'!D11:E76,2,1) -> Kiến thức về hệ thống nối đất | F13: 2 | G13: 2 | H13: 4 | I13: 4 | J13: 4 | K13: 4 | L13: 5 | M13: 5
B14: =INDEX('Ma trận năng lực'!B:B, MATCH(D14, 'Ma trận năng lực'!D:D, 0)) -> Công cụ, Dụng cụ cầm tay cho chuyên môn thiết bị HTĐK | C14: =ROW()-5 -> 9 | D14: ĐK_NLCM_009 | E14: =VLOOKUP(D14,'Ma trận năng lực'!D12:E77,2,1) -> Kiến thức và kỹ năng sử dụng công cụ dụng cụ cầm tay thuộc chuyên môn thiết bị HTĐK | F14: 1 | G14: 4 | H14: 3 | I14: 4 | J14: 4 | K14: 5 | L14: 5 | M14: 5
B15: =INDEX('Ma trận năng lực'!B:B, MATCH(D15, 'Ma trận năng lực'!D:D, 0)) -> P&ID | C15: =ROW()-5 -> 10 | D15: ĐK_NLCM_010 | E15: =VLOOKUP(D15,'Ma trận năng lực'!D13:E78,2,1) -> Kiến thức và kỹ năng về P&ID | F15: 1 | G15: 3 | H15: 2 | I15: 2 | J15: 2 | K15: 2 | L15: 2 | M15: 2
B16: =INDEX('Ma trận năng lực'!B:B, MATCH(D16, 'Ma trận năng lực'!D:D, 0)) -> Công nghệ sản xuất | C16: =ROW()-5 -> 11 | D16: ĐK_NLCM_016 | E16: =VLOOKUP(D16,'Ma trận năng lực'!D14:E79,2,1) -> Kiến thức cơ bản về quy trình công nghệ sản xuất tại Nhà máy Đạm Cà Mau từ khí đầu vào đến tạo hạt, đóng bao. | F16: 1 | G16: 2 | H16: 2 | I16: 2 | J16: 2 | K16: 2 | L16: 2 | M16: 2
B17: =INDEX('Ma trận năng lực'!B:B, MATCH(D17, 'Ma trận năng lực'!D:D, 0)) -> Tổng quan Hệ thống điều khiển nhà máy Đạm Cà Mau | C17: =ROW()-5 -> 12 | D17: ĐK_NLCM_017 | E17: =VLOOKUP(D17,'Ma trận năng lực'!D15:E80,2,1) -> Nắm được chức năng của các hệ thống điều khiển tại nhà máy Đạm Cà Mau bao gồm Hệ thống điều khiển phân tán, ESD, hệ thống điều khiển Turbine và máy nén, hệ thống MPS/MMS, hệ thống đóng bao xuất hàng | F17: 1 | G17: 2 | H17: 2 | I17: 2 | J17: 2 | K17: 2 | L17: 2 | M17: 2
B18: =INDEX('Ma trận năng lực'!B:B, MATCH(D18, 'Ma trận năng lực'!D:D, 0)) -> Tổng quan Thiết bị đo lường và van điều khiển nhà máy Đạm Cà Mau | C18: =ROW()-5 -> 13 | D18: ĐK_NLCM_018 | E18: =VLOOKUP(D18,'Ma trận năng lực'!D16:E81,2,1) -> Kiến thức về thiết bị đo lường và van điều khiển tại nhà máy Đạm Cà Mau | F18: 1 | G18: 2 | H18: 2 | I18: 2 | J18: 2 | K18: 2 | L18: 2 | M18: 2
... B24: =INDEX('Ma trận năng lực'!B:B, MATCH(D24, 'Ma trận năng lực'!D:D, 0)) -> Trí tuệ nhân tạo (AI) | C24: =ROW()-5 -> 19 | D24: ĐK_NLCM_024 | E24: =VLOOKUP(D24,'Ma trận năng lực'!D22:E87,2,1) -> Kiến thức và kỹ năng liên về trí tuệ nhân tạo (AI) | F24: 3 | G24: 4 | H24: 4 | I24: 4 | J24: 4 | K24: 4 | L24: 5 | M24: 5
A25: Trung cấp | B25: =INDEX('Ma trận năng lực'!B:B, MATCH(D25, 'Ma trận năng lực'!D:D, 0)) -> Hệ thống Fire Alarm- FA & Automatic Fire Fighting System- AFFS | C25: =ROW()-5 -> 20 | D25: ĐK_NLCM_025 | E25: =VLOOKUP(D25,'Ma trận năng lực'!D23:E88,2,1) -> Kiến thức và kỹ năng liên quan đến hệ thống FA & AFFS | F25: 1 | G25: 2 | H25: 4 | I25: 4 | J25: 4 | K25: 4 | L25: 4 | M25: 5
B26: =INDEX('Ma trận năng lực'!B:B, MATCH(D26, 'Ma trận năng lực'!D:D, 0)) -> Phần cứng hệ thống MPS/MMS | C26: =ROW()-5 -> 21 | D26: ĐK_NLCM_026 | E26: =VLOOKUP(D26,'Ma trận năng lực'!D24:E89,2,1) -> Kiến trúc phần cứng hệ thống MPS/MMS | F26: 1 | G26: 4 | H26: 3 | I26: 4 | J26: 4 | K26: 5 | L26: 5 | M26: 5
B27: =INDEX('Ma trận năng lực'!B:B, MATCH(D27, 'Ma trận năng lực'!D:D, 0)) -> Phần mềm hệ thống MPS/MMS | C27: =ROW()-5 -> 22 | D27: ĐK_NLCM_027 | E27: =VLOOKUP(D27,'Ma trận năng lực'!D25:E90,2,1) -> Kiến trúc phần mềm hệ thống MPS/MMS | F27: 1 | G27: 3 | H27: 4 | I27: 4 | J27: 4 | K27: 4 | L27: 5 | M27: 5
B28: =INDEX('Ma trận năng lực'!B:B, MATCH(D28, 'Ma trận năng lực'!D:D, 0)) -> Phần cứng hệ thống DCS | C28: =ROW()-5 -> 23 | D28: ĐK_NLCM_028 | E28: =VLOOKUP(D28,'Ma trận năng lực'!D26:E91,2,1) -> Kiến thức và kỹ năng liên quan đến phần cứng hệ thống DCS | F28: 1 | G28: 4 | H28: 3 | I28: 4 | J28: 4 | K28: 4 | L28: 4 | M28: 5
B29: =INDEX('Ma trận năng lực'!B:B, MATCH(D29, 'Ma trận năng lực'!D:D, 0)) -> Phần mềm hệ thống DCS | C29: =ROW()-5 -> 24 | D29: ĐK_NLCM_029 | E29: =VLOOKUP(D29,'Ma trận năng lực'!D27:E92,2,1) -> Kiến thức và kỹ năng liên quan đến phần mềm hệ thống DCS | F29: 1 | G29: 3 | H29: 3 | I29: 4 | J29: 4 | K29: 5 | L29: 5 | M29: 5
B30: =INDEX('Ma trận năng lực'!B:B, MATCH(D30, 'Ma trận năng lực'!D:D, 0)) -> Phần cứng hệ thống F&G | C30: =ROW()-5 -> 25 | D30: ĐK_NLCM_030 | E30: =VLOOKUP(D30,'Ma trận năng lực'!D28:E93,2,1) -> Kiến trúc phần cứng hệ thống F&G | F30: 1 | G30: 2 | H30: 4 | I30: 4 | J30: 4 | K30: 4 | L30: 5 | M30: 5
B31: =INDEX('Ma trận năng lực'!B:B, MATCH(D31, 'Ma trận năng lực'!D:D, 0)) -> Phần mềm hệ thống F&G | C31: =ROW()-5 -> 26 | D31: ĐK_NLCM_031 | E31: =VLOOKUP(D31,'Ma trận năng lực'!D29:E94,2,1) -> Kiến trúc phần mềm hệ thống F&G | F31: 1 | G31: 2 | H31: 3 | I31: 4 | J31: 4 | K31: 4 | L31: 4 | M31: 5
B32: =INDEX('Ma trận năng lực'!B:B, MATCH(D32, 'Ma trận năng lực'!D:D, 0)) -> Phần cứng hệ thống ESD | C32: =ROW()-5 -> 27 | D32: ĐK_NLCM_032 | E32: =VLOOKUP(D32,'Ma trận năng lực'!D30:E95,2,1) -> Kiến trúc phần cứng hệ thống ESD | F32: 1 | G32: 4 | H32: 3 | I32: 4 | J32: 4 | K32: 4 | L32: 5 | M32: 5
B33: =INDEX('Ma trận năng lực'!B:B, MATCH(D33, 'Ma trận năng lực'!D:D, 0)) -> Phần mềm hệ thống ESD | C33: =ROW()-5 -> 28 | D33: ĐK_NLCM_033 | E33: =VLOOKUP(D33,'Ma trận năng lực'!D31:E96,2,1) -> Kiến trúc phần mềm hệ thống ESD | F33: 1 | G33: 3 | H33: 4 | I33: 4 | J33: 4 | K33: 4 | L33: 4 | M33: 5
B34: =INDEX('Ma trận năng lực'!B:B, MATCH(D34, 'Ma trận năng lực'!D:D, 0)) -> Phần cứng hệ thống PLC | C34: =ROW()-5 -> 29 | D34: ĐK_NLCM_034 | E34: =VLOOKUP(D34,'Ma trận năng lực'!D32:E97,2,1) -> Kiến thức và kỹ năng liên quan đến phần cứng hệ thống PLC | F34: 1 | G34: 3 | H34: 3 | I34: 3 | J34: 3 | K34: 3 | L34: 4 | M34: 5
B35: =INDEX('Ma trận năng lực'!B:B, MATCH(D35, 'Ma trận năng lực'!D:D, 0)) -> Phần mềm hệ thống PLC | C35: =ROW()-5 -> 30 | D35: ĐK_NLCM_035 | E35: =VLOOKUP(D35,'Ma trận năng lực'!D33:E98,2,1) -> Kiến trúc và kỹ năng liên quan đến phần mềm hệ thống PLC | F35: 1 | G35: 3 | H35: 3 | I35: 3 | J35: 3 | K35: 4 | L35: 4 | M35: 5
B36: =INDEX('Ma trận năng lực'!B:B, MATCH(D36, 'Ma trận năng lực'!D:D, 0)) -> Hệ thống PLC nâng cao | C36: =ROW()-5 -> 31 | D36: ĐK_NLCM_036 | E36: =VLOOKUP(D36,'Ma trận năng lực'!D34:E99,2,1) -> Kiến trúc và kỹ năng nâng cao liên quan đến hệ thống PLC | F36: 1 | G36: 2 | H36: 3 | I36: 3 | J36: 3 | K36: 4 | L36: 4 | M36: 5
B37: =INDEX('Ma trận năng lực'!B:B, MATCH(D37, 'Ma trận năng lực'!D:D, 0)) -> Hệ thống DCS nâng cao | C37: =ROW()-5 -> 32 | D37: ĐK_NLCM_037 | E37: =VLOOKUP(D37,'Ma trận năng lực'!D35:E100,2,1) -> Kiến thức và kỹ năng chuyên sâu liên quan đến hệ thống DCS | F37: 1 | G37: 2 | H37: 3 | I37: 3 | J37: 3 | K37: 3 | L37: 4 | M37: 5
... B43: =INDEX('Ma trận năng lực'!B:B, MATCH(D43, 'Ma trận năng lực'!D:D, 0)) -> Hệ thống APC | C43: =ROW()-5 -> 38 | D43: ĐK_NLCM_043 | E43: =VLOOKUP(D43,'Ma trận năng lực'!D41:E106,2,1) -> Kiến thức về hệ thống APC | F43: 1 | G43: 2 | H43: 2 | I43: 2 | J43: 2 | K43: 3 | L43: 4 | M43: 5
A44: Nâng cao | B44: =INDEX('Ma trận năng lực'!B:B, MATCH(D44, 'Ma trận năng lực'!D:D, 0)) -> Quy trình làm việc nâng cao | C44: =ROW()-5 -> 39 | D44: ĐK_NLCM_054 | E44: =VLOOKUP(D44,'Ma trận năng lực'!D42:E107,2,1) -> Kiến thức về qui trình làm việc nâng cao | F44: 1 | G44: 1 | H44: 3 | I44: 3 | J44: 3 | K44: 3 | L44: 4 | M44: 5
B45: =INDEX('Ma trận năng lực'!B:B, MATCH(D45, 'Ma trận năng lực'!D:D, 0)) -> Thiết kế và triển khai các dự án C&I quy mô nhỏ | C45: =ROW()-5 -> 40 | D45: ĐK_NLCM_055 | E45: =VLOOKUP(D45,'Ma trận năng lực'!D43:E108,2,1) -> Tham gia thiết kế và triển khai các dự án C&I quy mô nhỏ | F45: 1 | G45: 1 | H45: 3 | I45: 3 | J45: 3 | K45: 3 | L45: 4 | M45: 5
B46: =INDEX('Ma trận năng lực'!B:B, MATCH(D46, 'Ma trận năng lực'!D:D, 0)) -> An toàn điều khiển chức năng | C46: =ROW()-5 -> 41 | D46: ĐK_NLCM_056 | E46: =VLOOKUP(D46,'Ma trận năng lực'!D44:E109,2,1) -> Kiến thức về an toàn điều khiển chức năng | F46: 1 | G46: 1 | H46: 3 | I46: 3 | J46: 3 | K46: 3 | L46: 4 | M46: 5
B47: =INDEX('Ma trận năng lực'!B:B, MATCH(D47, 'Ma trận năng lực'!D:D, 0)) -> Điều khiển nâng cao | C47: =ROW()-5 -> 42 | D47: ĐK_NLCM_057 | E47: =VLOOKUP(D47,'Ma trận năng lực'!D45:E110,2,1) -> Kiến thức và kỹ năng liên quan đến điều khiển nâng cao | F47: 1 | G47: 1
A48: Nghiệp vụ hành chính | B48: =INDEX('Ma trận năng lực'!B:B, MATCH(D48, 'Ma trận năng lực'!D:D, 0)) -> Quản lý hồ sơ, tài liệu/bản vẽ kỹ thuật | C48: =ROW()-5 -> 43 | D48: ĐK_NLCM_064 | E48: =VLOOKUP(D48,'Ma trận năng lực'!D46:E111,2,1) -> Quản lý hồ sơ, tài liệu/bản vẽ kỹ thuật
B49: =INDEX('Ma trận năng lực'!B:B, MATCH(D49, 'Ma trận năng lực'!D:D, 0)) -> Quản lý sử dụng vật tư tiêu hao, thiết bị, CCDC | C49: =ROW()-5 -> 44 | D49: ĐK_NLCM_065 | E49: =VLOOKUP(D49,'Ma trận năng lực'!D47:E112,2,1) -> Quản lý sử dụng vật tư tiêu hao, thiết bị, CCDC
C50: =ROW()-5 -> 45 | D50: ĐK_NLCM_066 | E50: =VLOOKUP(D50,'Ma trận năng lực'!D48:E113,2,1) -> Kỹ năng sử dụng SAP

Sheet KNL_ĐK_12
A1: KHUNG NĂNG LỰC CHUYÊN MÔN
A2: Kỹ thuật viên Kỹ thuật viên trực ca điều khiển (KNL_ĐK_12)
A3: Phân nhóm | B3: Năng lực chuyên môn | C3: Stt | D3: Mã năng lực | E3: Chi tiết năng lực chuyên môn | F3: Bậc 1 | G3: Bậc 2 | H3: Bậc 3 | I3: Bậc 4 | J3: Bậc 5 | K3: Bậc 6 | L3: Bậc 7 | M3: Bậc 8
F4: =SUM(F6:F55) -> 58 | G4: =SUM(G6:G55) -> 68 | H4: =SUM(H6:H55) -> 87 | I4: =SUM(I6:I55) -> 104 | J4: =SUM(J6:J55) -> 107 | K4: =SUM(K6:K55) -> 111 | L4: =SUM(L6:L55) -> 116 | M4: =SUM(M6:M55) -> 116
F5: 1 | G5: 2 | H5: 3 | I5: 4 | J5: 5 | K5: 6 | L5: 7 | M5: 8
A6: Cơ bản | B6: =INDEX('Ma trận năng lực'!B:B, MATCH(D6, 'Ma trận năng lực'!D:D, 0)) -> HSE cương vị | C6: =ROW()-5 -> 1 | D6: {=_xlfn._xlws.FILTER('Ma trận năng lực'!D:D,'Ma trận năng lực'!U:U="x")} -> ĐK_NLCM_001 | E6: =VLOOKUP(D6,'Ma trận năng lực'!D4:E69,2,1) -> Kiến thức về an toàn khi làm việc với các thiết bị đo lường tự động hóa | F6: 2 | G6: 3 | H6: 4 | I6: 4 | J6: 4 | K6: 4 | L6: 4 | M6: 4
B7: =INDEX('Ma trận năng lực'!B:B, MATCH(D7, 'Ma trận năng lực'!D:D, 0)) -> Quy trình làm việc | C7: =ROW()-5 -> 2 | D7: ĐK_NLCM_002 | E7: =VLOOKUP(D7,'Ma trận năng lực'!D5:E70,2,1) -> Kiến thức về quy trình làm việc | F7: 2 | G7: 3 | H7: 4 | I7: 4 | J7: 4 | K7: 4 | L7: 4 | M7: 4
B8: =INDEX('Ma trận năng lực'!B:B, MATCH(D8, 'Ma trận năng lực'!D:D, 0)) -> Nhận diện mối nguy và đánh giá rủi ro | C8: =ROW()-5 -> 3 | D8: ĐK_NLCM_003 | E8: =VLOOKUP(D8,'Ma trận năng lực'!D6:E71,2,1) -> Nhận diện mối nguy và đánh giá rủi ro | F8: 2 | G8: 3 | H8: 3 | I8: 3 | J8: 4 | K8: 4 | L8: 4 | M8: 4
B9: =INDEX('Ma trận năng lực'!B:B, MATCH(D9, 'Ma trận năng lực'!D:D, 0)) -> Nền tảng chuyên ngành đo lường điều khiển | C9: =ROW()-5 -> 4 | D9: ĐK_NLCM_004 | E9: =VLOOKUP(D9,'Ma trận năng lực'!D7:E72,2,1) -> Kiến thức Điện - Điện tử cơ bản | F9: 2 | G9: 3 | H9: 4 | I9: 4 | J9: 4 | K9: 4 | L9: 4 | M9: 4
B10: =INDEX('Ma trận năng lực'!B:B, MATCH(D10, 'Ma trận năng lực'!D:D, 0)) -> P&ID | C10: =ROW()-5 -> 5 | D10: ĐK_NLCM_010 | E10: =VLOOKUP(D10,'Ma trận năng lực'!D8:E73,2,1) -> Kiến thức và kỹ năng về P&ID | F10: 2 | G10: 3 | H10: 3 | I10: 3 | J10: 4 | K10: 4 | L10: 4 | M10: 4
B11: =INDEX('Ma trận năng lực'!B:B, MATCH(D11, 'Ma trận năng lực'!D:D, 0)) -> IO wiring, Instrument juction box và cable schedule và Interlock | C11: =ROW()-5 -> 6 | D11: ĐK_NLCM_011 | E11: =VLOOKUP(D11,'Ma trận năng lực'!D9:E74,2,1) -> Kiến thức về IO wiring, Instrument juction box và cable schedule, Interlock | F11: 2 | G11: 3 | H11: 3 | I11: 4 | J11: 4 | K11: 4 | L11: 4 | M11: 4
B12: =INDEX('Ma trận năng lực'!B:B, MATCH(D12, 'Ma trận năng lực'!D:D, 0)) -> Công cụ, Dụng cụ cầm tay cho chuyên môn thiết bị Đo lường | C12: =ROW()-5 -> 7 | D12: ĐK_NLCM_012 | E12: =VLOOKUP(D12,'Ma trận năng lực'!D10:E75,2,1) -> Kỹ năng sử dụng Công cụ, Dụng cụ cầm tay cho chuyên môn thiết bị Đo lường | F12: 2 | G12: 3 | H12: 3 | I12: 3 | J12: 3 | K12: 3 | L12: 4 | M12: 4
B13: =INDEX('Ma trận năng lực'!B:B, MATCH(D13, 'Ma trận năng lực'!D:D, 0)) -> Công cụ, Dụng cụ cầm tay cho chuyên môn thiết bị van điều khiển | C13: =ROW()-5 -> 8 | D13: ĐK_NLCM_013 | E13: =VLOOKUP(D13,'Ma trận năng lực'!D11:E76,2,1) -> Kỹ năng sử dụng Công cụ, Dụng cụ cầm tay cho chuyên môn thiết bị van điều khiển | F13: 2 | G13: 2 | H13: 3 | I13: 3 | J13: 4 | K13: 4 | L13: 4 | M13: 4
B14: =INDEX('Ma trận năng lực'!B:B, MATCH(D14, 'Ma trận năng lực'!D:D, 0)) -> Vật lý cơ bản | C14: =ROW()-5 -> 9 | D14: ĐK_NLCM_014 | E14: =VLOOKUP(D14,'Ma trận năng lực'!D12:E77,2,1) -> Kiến thức về vật lý và đại lượng đo lường cơ bản | F14: 2 | G14: 3 | H14: 3 | I14: 4 | J14: 4 | K14: 4 | L14: 4 | M14: 4
B15: =INDEX('Ma trận năng lực'!B:B, MATCH(D15, 'Ma trận năng lực'!D:D, 0)) -> Lựa chọn fitting, tubing | C15: =ROW()-5 -> 10 | D15: ĐK_NLCM_015 | E15: =VLOOKUP(D15,'Ma trận năng lực'!D13:E78,2,1) -> Kiến thức và kỹ năng liên quan đến lựa chọn fitting và tubing | F15: 2 | G15: 2 | H15: 2 | I15: 2 | J15: 2 | K15: 2 | L15: 2 | M15: 2
B16: =INDEX('Ma trận năng lực'!B:B, MATCH(D16, 'Ma trận năng lực'!D:D, 0)) -> Công nghệ sản xuất | C16: =ROW()-5 -> 11 | D16: ĐK_NLCM_016 | E16: =VLOOKUP(D16,'Ma trận năng lực'!D14:E79,2,1) -> Kiến thức cơ bản về quy trình công nghệ sản xuất tại Nhà máy Đạm Cà Mau từ khí đầu vào đến tạo hạt, đóng bao. | F16: 2 | G16: 2 | H16: 3 | I16: 3 | J16: 3 | K16: 3 | L16: 3 | M16: 3
B17: =INDEX('Ma trận năng lực'!B:B, MATCH(D17, 'Ma trận năng lực'!D:D, 0)) -> Tổng quan Hệ thống điều khiển nhà máy Đạm Cà Mau | C17: =ROW()-5 -> 12 | D17: ĐK_NLCM_017 | E17: =VLOOKUP(D17,'Ma trận năng lực'!D15:E80,2,1) -> Nắm được chức năng của các hệ thống điều khiển tại nhà máy Đạm Cà Mau bao gồm Hệ thống điều khiển phân tán, ESD, hệ thống điều khiển Turbine và máy nén, hệ thống MPS/MMS, hệ thống đóng bao xuất hàng | F17: 2 | G17: 2 | H17: 3 | I17: 3 | J17: 3 | K17: 4 | L17: 4 | M17: 4
B18: =INDEX('Ma trận năng lực'!B:B, MATCH(D18, 'Ma trận năng lực'!D:D, 0)) -> Tổng quan Thiết bị đo lường và van điều khiển nhà máy Đạm Cà Mau | C18: =ROW()-5 -> 13 | D18: ĐK_NLCM_018 | E18: =VLOOKUP(D18,'Ma trận năng lực'!D16:E81,2,1) -> Kiến thức về thiết bị đo lường và van điều khiển tại nhà máy Đạm Cà Mau | F18: 2 | G18: 2 | H18: 3 | I18: 3 | J18: 3 | K18: 4 | L18: 4 | M18: 4
... B20: =INDEX('Ma trận năng lực'!B:B, MATCH(D20, 'Ma trận năng lực'!D:D, 0)) -> Kiến thức tổng quan về biện pháp phòng nổ (Ex protection) | C20: =ROW()-5 -> 15 | D20: ĐK_NLCM_020 | E20: =VLOOKUP(D20,'Ma trận năng lực'!D18:E83,2,1) -> Kiến thức về ký hiệu phòng nổ trên thiết bị | F20: 2 | G20: 2 | H20: 3 | I20: 4 | J20: 4 | K20: 4 | L20: 4 | M20: 4
A21: Trung cấp | B21: =INDEX('Ma trận năng lực'!B:B, MATCH(D21, 'Ma trận năng lực'!D:D, 0)) -> Trí tuệ nhân tạo (AI) | C21: =ROW()-5 -> 16 | D21: ĐK_NLCM_024 | E21: =VLOOKUP(D21,'Ma trận năng lực'!D19:E84,2,1) -> Kiến thức và kỹ năng liên về trí tuệ nhân tạo (AI) | F21: 2 | G21: 2 | H21: 3 | I21: 4 | J21: 4 | K21: 4 | L21: 4 | M21: 4
B22: =INDEX('Ma trận năng lực'!B:B, MATCH(D22, 'Ma trận năng lực'!D:D, 0)) -> Thiết bị đo nhiệt độ | C22: =ROW()-5 -> 17 | D22: ĐK_NLCM_044 | E22: =VLOOKUP(D22,'Ma trận năng lực'!D20:E85,2,1) -> Kiến thức và kỹ năng về thiết bị đo nhiệt độ | F22: 2 | G22: 2 | H22: 3 | I22: 4 | J22: 4 | K22: 4 | L22: 4 | M22: 4
B23: =INDEX('Ma trận năng lực'!B:B, MATCH(D23, 'Ma trận năng lực'!D:D, 0)) -> Thiết bị đo áp suất | C23: =ROW()-5 -> 18 | D23: ĐK_NLCM_045 | E23: =VLOOKUP(D23,'Ma trận năng lực'!D21:E86,2,1) -> Kiến thức và kỹ năng về thiết bị đo áp suất | F23: 2 | G23: 2 | H23: 3 | I23: 4 | J23: 4 | K23: 4 | L23: 4 | M23: 4
B24: =INDEX('Ma trận năng lực'!B:B, MATCH(D24, 'Ma trận năng lực'!D:D, 0)) -> Thiết bị đo mức theo nguyên lý chênh áp | C24: =ROW()-5 -> 19 | D24: ĐK_NLCM_046 | E24: =VLOOKUP(D24,'Ma trận năng lực'!D22:E87,2,1) -> Kiến thức và kỹ năng về thiết bị đo mức theo nguyên lý chênh áp | F24: 2 | G24: 2 | H24: 3 | I24: 4 | J24: 4 | K24: 4 | L24: 4 | M24: 4
B25: =INDEX('Ma trận năng lực'!B:B, MATCH(D25, 'Ma trận năng lực'!D:D, 0)) -> Thiết bị đo lưu lượng theo nguyên lý chênh áp | C25: =ROW()-5 -> 20 | D25: ĐK_NLCM_047 | E25: =VLOOKUP(D25,'Ma trận năng lực'!D23:E88,2,1) -> Kiến thức và kỹ năng về thiết bị đo lưu lượng theo nguyên lý chênh áp | F25: 2 | G25: 2 | H25: 3 | I25: 4 | J25: 4 | K25: 4 | L25: 4 | M25: 4
B26: =INDEX('Ma trận năng lực'!B:B, MATCH(D26, 'Ma trận năng lực'!D:D, 0)) -> Thiết bị đo giám sát máy động | C26: =ROW()-5 -> 21 | D26: ĐK_NLCM_048 | E26: =VLOOKUP(D26,'Ma trận năng lực'!D24:E89,2,1) -> Kiến thức và kỹ năng về thiết bị đo giám sát máy động | F26: 2 | G26: 2 | H26: 3 | I26: 4 | J26: 4 | K26: 4 | L26: 4 | M26: 4
B27: =INDEX('Ma trận năng lực'!B:B, MATCH(D27, 'Ma trận năng lực'!D:D, 0)) -> Van điều khiển với cơ cấu chấp hành khí nén (Pneumatic actuator) | C27: =ROW()-5 -> 22 | D27: ĐK_NLCM_049 | E27: =VLOOKUP(D27,'Ma trận năng lực'!D25:E90,2,1) -> Kiến thức và kỹ năng về van điều khiển với cơ cấu chấp hành khí nén (Pneumatic actuator) | F27: 2 | G27: 2 | H27: 3 | I27: 4 | J27: 4 | K27: 4 | L27: 4 | M27: 4
B28: =INDEX('Ma trận năng lực'!B:B, MATCH(D28, 'Ma trận năng lực'!D:D, 0)) -> Thiết bị phân tích, quan trắc môi trường | C28: =ROW()-5 -> 23 | D28: ĐK_NLCM_050 | E28: =VLOOKUP(D28,'Ma trận năng lực'!D26:E91,2,1) -> Kiến thức và kỹ năng về thiết bị phân tích, quan trắc môi trường | F28: 2 | G28: 3 | H28: 3 | I28: 4 | J28: 4 | K28: 4 | L28: 4 | M28: 4
B29: =INDEX('Ma trận năng lực'!B:B, MATCH(D29, 'Ma trận năng lực'!D:D, 0)) -> Thiết bị dò khí cháy nổ và khí độc | C29: =ROW()-5 -> 24 | D29: ĐK_NLCM_051 | E29: =VLOOKUP(D29,'Ma trận năng lực'!D27:E92,2,1) -> Kiến thức và kỹ năng về thiết bị dò khí cháy nổ và khí độc | F29: 2 | G29: 3 | H29: 3 | I29: 4 | J29: 4 | K29: 4 | L29: 4 | M29: 4
A30: Nâng cao | B30: =INDEX('Ma trận năng lực'!B:B, MATCH(D30, 'Ma trận năng lực'!D:D, 0)) -> Thiết bị đóng bao | C30: =ROW()-5 -> 25 | D30: ĐK_NLCM_052 | E30: =VLOOKUP(D30,'Ma trận năng lực'!D28:E93,2,1) -> Kiến thức và kỹ năng về thiết bị đóng bao | F30: 2 | G30: 2 | H30: 3 | I30: 3 | J30: 3 | K30: 3 | L30: 4 | M30: 4
B31: =INDEX('Ma trận năng lực'!B:B, MATCH(D31, 'Ma trận năng lực'!D:D, 0)) -> Thiết bị vận chuyển, xuất hàng, lưu kho, nhập liệu | C31: =ROW()-5 -> 26 | D31: ĐK_NLCM_053 | E31: =VLOOKUP(D31,'Ma trận năng lực'!D29:E94,2,1) -> Kiến thức và kỹ năng về thiết bị vận chuyển, xuất hàng, lưu kho, nhập liệu | F31: 2 | G31: 2 | H31: 3 | I31: 3 | J31: 3 | K31: 3 | L31: 4 | M31: 4
B32: =INDEX('Ma trận năng lực'!B:B, MATCH(D32, 'Ma trận năng lực'!D:D, 0)) -> Thiết bị đo mức không theo nguyên lý chênh áp | C32: =ROW()-5 -> 27 | D32: ĐK_NLCM_058 | E32: =VLOOKUP(D32,'Ma trận năng lực'!D30:E95,2,1) -> Kiến thức và kỹ năng về Thiết bị đo mức không theo nguyên lý chênh áp | F32: 2 | G32: 2 | H32: 3 | I32: 3 | J32: 3 | K32: 3 | L32: 4 | M32: 4
B33: =INDEX('Ma trận năng lực'!B:B, MATCH(D33, 'Ma trận năng lực'!D:D, 0)) -> Thiết bị đo lưu lượng không theo nguyên lý chênh áp | C33: =ROW()-5 -> 28 | D33: ĐK_NLCM_059 | E33: =VLOOKUP(D33,'Ma trận năng lực'!D31:E96,2,1) -> Kiến thức và kỹ năng về Thiết bị đo lưu lượng không theo nguyên lý chênh áp | F33: 1 | G33: 1 | H33: 1 | I33: 2 | J33: 2 | K33: 2 | L33: 2 | M33: 2
B34: =INDEX('Ma trận năng lực'!B:B, MATCH(D34, 'Ma trận năng lực'!D:D, 0)) -> Lựa chọn thiết bị đo lường | C34: =ROW()-5 -> 29 | D34: ĐK_NLCM_060 | E34: =VLOOKUP(D34,'Ma trận năng lực'!D32:E97,2,1) -> Kiến thức liên quan đến lựa chọn thiết bị đo lường | F34: 1 | G34: 1 | H34: 1 | I34: 3 | J34: 3 | K34: 3 | L34: 4 | M34: 4
B35: =INDEX('Ma trận năng lực'!B:B, MATCH(D35, 'Ma trận năng lực'!D:D, 0)) -> Van điều khiển với cơ cấu chấp hành motor (MOV) | C35: =ROW()-5 -> 30 | D35: ĐK_NLCM_061 | E35: =VLOOKUP(D35,'Ma trận năng lực'!D33:E98,2,1) -> Kiến thức và kỹ năng về van điều khiển với cơ cấu chấp hành motor (MOV) | F35: 1 | G35: 1 | H35: 1 | I35: 2 | J35: 2 | K35: 3 | L35: 3 | M35: 3
B36: =INDEX('Ma trận năng lực'!B:B, MATCH(D36, 'Ma trận năng lực'!D:D, 0)) -> Van điều khiển với cơ cấu chấp hành thủy lực | C36: =ROW()-5 -> 31 | D36: ĐK_NLCM_062 | E36: =VLOOKUP(D36,'Ma trận năng lực'!D34:E99,2,1) -> Kiến thức và kỹ năng về van điều khiển với cơ cấu chấp hành thủy lực | F36: 1 | G36: 1 | H36: 1 | I36: 2 | J36: 2 | K36: 2 | L36: 2 | M36: 2
A37: Nghiệp vụ hành chính | B37: =INDEX('Ma trận năng lực'!B:B, MATCH(D37, 'Ma trận năng lực'!D:D, 0)) -> Lựa chọn thiết bị van điều khiển | C37: =ROW()-5 -> 32 | D37: ĐK_NLCM_063 | E37: =VLOOKUP(D37,'Ma trận năng lực'!D35:E100,2,1) -> Kiến thức liên quan đến lựa chọn thiết bị van điều khiển
B38: =INDEX('Ma trận năng lực'!B:B, MATCH(D38, 'Ma trận năng lực'!D:D, 0)) -> Quản lý hồ sơ, tài liệu/bản vẽ kỹ thuật | C38: =ROW()-5 -> 33 | D38: ĐK_NLCM_064 | E38: =VLOOKUP(D38,'Ma trận năng lực'!D36:E101,2,1) -> Quản lý hồ sơ, tài liệu/bản vẽ kỹ thuật
B39: =INDEX('Ma trận năng lực'!B:B, MATCH(D39, 'Ma trận năng lực'!D:D, 0)) -> Quản lý sử dụng vật tư tiêu hao, thiết bị, CCDC | C39: =ROW()-5 -> 34 | D39: ĐK_NLCM_065 | E39: =VLOOKUP(D39,'Ma trận năng lực'!D37:E102,2,1) -> Quản lý sử dụng vật tư tiêu hao, thiết bị, CCDC
D40: ĐK_NLCM_066

Sheet KNL_ĐK_13
A1: KHUNG NĂNG LỰC CHUYÊN MÔN
A2: Kỹ thuật viên BDSC thiết bị đo lường (KNL_ĐK_13)
A3: Phân nhóm | B3: Năng lực chuyên môn | C3: Stt | D3: Mã năng lực | E3: Chi tiết năng lực chuyên môn | F3: Bậc 1 | G3: Bậc 2 | H3: Bậc 3 | I3: Bậc 4 | J3: Bậc 5 | K3: Bậc 6 | L3: Bậc 7 | M3: Bậc 8
F4: =SUM(F6:F57) -> 26 | G4: =SUM(G6:G57) -> 58 | H4: =SUM(H6:H57) -> 62 | I4: =SUM(I6:I57) -> 65 | J4: =SUM(J6:J57) -> 68 | K4: =SUM(K6:K57) -> 70 | L4: =SUM(L6:L57) -> 73 | M4: =SUM(M6:M57) -> 75
