Workbook
Name cn: '[1]Trường cố định'!$A$2:$A$6
Name kq: '[2]Trường cố định'!$D$2:$D$3
Name lh: '[1]Trường cố định'!$B$2:$B$4
Name ncm: '[2]Trường cố định'!$E$2:$E$8
Name plgr: '[1]Trường cố định'!$C$2:$C$6
Name tth: '[1]Trường cố định'!$F$2:$F$12

Sheet 20
A2: NHÀ MÁY ĐẠM CÀ MAU | I2: CỘNG HÒA XÃ HỘI CHỦ NGHĨA VIỆT NAM
A3: XƯỞNG ĐIỀU KHIỂN | I3: Độc lập – Tự do – Hạnh phúc
H5: Cà Mau, ngày 18 tháng 05 năm 2026
H6: .
B7: BÁO CÁO TUẦN 20 VÀ KẾ HOẠCH TUẦN 21 NĂM 2026
B9: Xưởng Điều khiển báo cáo công việc thực hiện trong tuần như sau:
B10: I. CÔNG TÁC THỰC HIỆN BẢO DƯỠNG ĐỊNH KỲ
B11: TT | C11: Hạng mục công việc | D11: %WO thực hiện | E11: Tổng WO thực hiện trong tuần | F11: Tổng số WO đã thực hiện trong tháng | G11: Tổng số WO theo KH | H11: Tổng WO chưa thực hiện theo KH | I11: Lý do không thực hiện các WO trong tháng (nếu có) | J11: Đơn vị thực hiện | K11: Ghi chú | L11: TB đo | M11: TBCH | N11: HTĐK
B12: 1 | C12: Hạng mục thiết bị Điều khiển | D12: =F12/G12 -> 0.57542373 | E12: =O12 -> 346 | F12: =333+E12 -> 679 | G12: =O13 -> 1180 | H12: =G12-F12 -> 501 | J12: X. ĐK | L12: 115 | M12: 163 | N12: 68 | O12: =SUM(L12:N12) -> 346
B13: II. TÌNH HÌNH THỰC CÔNG VIỆC THEO KẾ HOẠCH NĂM | L13: 336 | M13: 608 | N13: 236 | O13: =SUM(L13:N13) -> 1180
B14: TT | C14: Hạng mục công việc | D14: Nội dung yêu cầu thực hiện | G14: Thời hạn hoàn thành | H14: Mức độ hoàn thành | I14: Tình hình thực hiện | J14: Đơn vị thực hiện | K14: Ghi chú | L14: TB đo | M14: TBCH | N14: HTĐK | O14: TCDK
B15: 1 | C15: Công tác STOP | D15: Khuyến khích CBCNV Xưởng tham gia chương trình | G15: Hàng tháng | H15: N/A | I15: - Số thẻ STOP trong tuần: ghi nhận 8 thẻ. - Số thẻ STOP tháng 05/2026: ghi nhận: 10 thẻ | J15: X. ĐK | L15: 0 | M15: 8 | N15: 0 | O15: 0 | P15: =SUM(L15:O15) -> 8
B16: 2 | C16: Công tác đào tạo năm 2026 | D16: Thực hiện đào tạo nội bộ theo kế hoạch trong năm 2026 | G16: 46387 | H16: =444/1126 -> 0.39431616 | I16: - Thực hiện trong tuần: 42 giờ. Tích lũy: 444/1126 giờ | J16: X. ĐK | L16: 16 | M16: 6 | N16: 8 | O16: 12 | P16: =SUM(L16:O16) -> 42
D17: Kế hoạch đào tạo bên ngoài | G17: 46387 | H17: N/A | I17: Chưa triển khai | J17: X. ĐK
B18: III. TÌNH HÌNH THỰC HIỆN CÁC HẠNG MỤC NÂNG CẤP, CẢI TIẾN, CẢI TẠO
B19: TT | C19: Hạng mục công việc | D19: Nội dung yêu cầu thực hiện | G19: Thời hạn hoàn thành | I19: Tình hình thực hiện | J19: Đơn vị thực hiện | K19: Ghi chú
B20: 1 | C20: Nghiên cứu triển khai lắp đặt hệ thống phun sơn tự động cho X.SP | D20: Nghiên cứu triển khai lắp đặt hệ thống phun sơn tự động cho X.SP V16 + Phun sơn tự động + Có thể linh hoạt di chuyển giữa các Line | G20: 46386 | H20: 0.92 | I20: - Hoàn thành lắp đặt hệ thống điều khiển, test máy phun sơn với nước đạt yêu cầu - Đang chờ đơn hàng sơn về để chạy test với sơn | J20: Đội TBCH | K20: Không thay đổi trong tuần
B21: 2 | C21: Cải tiến lại hệ thống robot NPK line A,B,C để gắp được bao 25kg | D21: Thực hiện các hạng mục công việc cần thiết để thực hiện cải tiến 3 line robot NPK A,B,C cho bao 25kg | G21: 46386 | H21: 0.95 | I21: - Hoàn thành lập trình tọa độ và cấu hình lớp bao cho loại bao 25kg - Hoàn thành chạy thử và bàn giao vận hành Line C - Line B chưa test được do không đóng bao 25kg | J21: Đội TBCH | K21: Không thay đổi trong tuần
B22: 3 | C22: Nâng cấp hệ thống F&G | D22: Phase 2: Triển khai thực hiện | G22: 30/09/2026 | H22: 0.43 | I22: FS: Báo cáo chủ trương đã được phê duyệt Front end and detail design: - Tình hình các đơn hàng: ĐH 1: Cung cấp vật tư đầu dò phục vụ lắp bổ sung đầu dò gas detector: KHMS (Điều chỉnh lại spec và trình lại YCMS vào tuần 21) ĐH 2: Cung cấp vật tư thiết bị hệ thống phục vụ lắp bổ sung đầu dò gas detector: KHMS (Đang soạn HSMCG) ĐH 3: Cung cấp dịch vụ thi công hạ tầng, lắp đặt thiết bị gas detector: KHMS (Đang soạn HSMCG) - Thiết kế kỹ thuật (100%) - Xây dựng phương án triển khai scope PVCFC (83%) (D/L: 30/05) | J22: Phạm Thanh Quyền
B23: 4 | C23: AHU H | D23: - Lắp lại PI, TI cho AHU - H - Lắp thêm sensor đo nhiệt độ trên AHU H. | F23: 45664 | G23: 31/07/2025 | H23: 1 | I23: - Nhận vật tư: Dây kéo dài TC-K, Thermowell - Đã đấu nối tín hiệu thiết bị đo TT. - Đã lắp lại PI - Tuần 11 đã khảo sát lại với Cơ khí xác định vị trí hàn lại TI. Cơ khí thông báo đang mua vật tư - Tuần 20 đã lắp lại TI sau khi CK hàn xong nozzle
B24: 5 | C24: Khắc phục tồn động hệ thống pccc từ Đoàn thanh tra Bộ Công an về công tác PCCC | D24: Tòa nhà khối bảo dưỡng: Rà soát lại các thiết kế hệ thống báo cháy theo thẩm duyệt: hệ thống nào có thiết kế điện trở cuối kênh hay không có điện trở cuối kênh phải đảm bảo đúng thiết kế. Phòng ATMT lập WR, X.ĐK thực hiện tại tòa nhà khối bảo dưỡng | G24: 30/03/2026 | H24: 100% | I24: Hoàn thành khắc phục các điểm sai khác bản vẽ thẩm duyệt Đã hoàn thành nghiệm thu với P.AT - P.ATMT kiểm tra lắp đặt điện trở cuối, điện trở cuối đã được lắp đặt theo đúng bản vẽ thẩm duyệt - P.ATMT tháo thiết bị bất kỳ tại các zone, tủ báo cháy hiển thị lỗi hở mạch zone đó. | J24: Tổ TBHTPC
D25: Các đầu báo cháy nằm cách trần nhà >0.3m. P.AT lập WR sau khi khảo sát và X.ĐK lên kế hoạch thực hiện | G25: 30/03/2026 | H25: 0.76 | I25: - Tích lũy thực hiện di dời đầu dò không cần giàn giáo: 35/35 đầu dò - Tích lũy thực hiện di dời có giàn giáo: 71/82 đầu dò - Tích lũy thực hiện lắp mới có giàn giáo: 21/21 đầu dò | J25: Tổ TBHTPC
D26: Mua sắm bổ sung các thiết bị test báo cháy phù hợp. P.ATMT lập kế hoạch mua sắm | G26: 30/03/2026 | H26: 0.85 | I26: Đã đưa vào kế hoạch mua sắm 2026 Đã lập danh mục đưa vào YCMS CCDC và đã gửi đầu mối xưởng triển khai mua sắm Kế hoạch tiếp theo: theo dõi mua sắm | J26: Tổ TBHTPC
B27: 6 | C27: Hệ thống FA lắp mới | D27: Phối hợp P.AT khảo sát các thiết bị báo cháy lắp mới cần kết nối về hệ thống trung tâm tại Nhà máy với bảng MIMIC | G27: 30/12/2025 | H27: 1 | I27: Hoàn thành phối hợp P.AT khảo sát xác định các khu vực chưa kết nối hệ thống Fire Alarm về hệ thống trung tâm và đưa ra yêu cầu có thứ tự ưu tiên. | J27: Tổ TBHTPC
D28: X. ĐK đánh giá tính khả thi về kỹ thuật và chi phí sơ bộ để thực hiện kết nối hệ thống Fire Alarm theo thứ tự ưu tiên của P. ATMT. | G28: 30/12/2025 | H28: 1 | I28: Hoàn thành bốc tách vật tư và chi phí thực hiện, đã trình bày trước LĐX Xưởng và được thông qua. Hoàn thành xin ý kiến LĐNM và đã triển khai YCMS VT | J28: Tổ TBHTPC
D29: Thiết kế hệ thống MIMIC phải đồng bộ với việc kết nối hệ thống Fire Alarm và F&G. | G29: 30/03/2026 | H29: 0.26 | I29: Hoàn thành cập nhật bản vẻ CAD và graphic F&G Đang liên hệ các nhà cung cấp đề thiết kế bản vẽ Hoàn thành vẽ graphic MIMIC PANEL mới tại máy tính FGS Đã xin ý kiến LĐX về các giải pháp: Gợi ý về bảng MIMIC mới: tìm hiểu về bảng MIMIC hiển thị bằng màn hình LED. Cập nhật bản vẽ CAD và graphic máy tính F&G: Hoàn thành Trong tuần: - Soạn phương án thực hiện kết nối các hệ thống báo cháy lắp mới: 70% Tuần sau: Soạn phương án thực hiện kết nối các hệ thống báo cháy lắp mới. Trao đổi với p.AT về giải pháp bảng MIMIC | J29: Tổ TBHTPC
B30: 7 | C30: Hệ thống PLC K04421 | D30: Nghiên cứu phương án lấy tín hiệu từ Trident K04421 về HMI Siemens PLC | G30: 01/09/2026 | H30: 0.6 | I30: Đã hoàn thành: - Thực hiện cấu hình thử nghiệm trên phần mềm WinccFlexible lấy dữ liệu qua đường truyền Modbus TCP/IP - Thực hiện cấu hình thử nghiệm trên phần mềm Tristation truyền Modbus TCP/IP đến thiết bị khác - Dùng phần mềm Modbus Slave để kiểm tra kết nối Modbus TCP/IP với Wincc Flexible - Đã trao đổi với Schneider về các phương án truyền dữ liệu giữa HMI Siemens và Trident, Schneider cần kiểm tra thêm Version V3.1 có hỗ trợ Modbus TCP/IP không. - Mô phỏng kết nối lấy dữ liệu tử Trident về WinCC Classic (PCS 7) qua DDE, trong trường hợp cần thiết có thế lấy dữ liệu từ Trident K04421 về HMI K04441 (Do HMI K04421 không hỗ trợ DDE, K04441 có thể kết nối lấy dữ liệu từ Trident qua DDE). - Nhắc Schneider kiểm tra thông tin Version V3.1 có hỗ trợ Modbus TCP/IP không để lên p/a thực hiện kết nối Trident với HMI trong BDTT 2026 - P. KTBD đã y/c Schneider kiểm tra thông tin Version V3.1 có hỗ trợ Modbus TCP/IP không để lên p/a thực hiện kết nối Trident với HMI trong BDTT 2026 - Lắp đặt xong phần cứng Trident để thử nghiệm truyền thông giữa HMI và Trident - Test kiểm tra xong kết nối modbus TCP/IP giữa Trident và HMI Siemens Trong tuần: Kiểm tra truyền giá trị giữa HMI và Trident, các tín hiệu truyền tốt tuy nhiên còn tín hiệu Setpoint giá trị Real từ HMI sang Trident chưa thực hiện được. Tuần sau: - Nghiên cứu truyền giá trị Setpoint Real từ HMI sang Trident - Soạn thảo phương án thực hiện trong BDTT 2026 | J30: Trịnh Văn Kiều
B31: 8 | C31: Cập nhật các tài liệu loop diagram, Interlock Logic diagram, Alarm trip setpoint | D31: Phối hợp P.KTBD và các Xưởng VH cập nhật các tài liệu Loop diagram, Interlock Logic diagram, Alarm trip setpoint | G31: N/A | H31: 0.52 | I31: 1. Interlock Logic diagram: - DCS: 0% - ESD: 0% - PLC: 0% - MPS: 100% 2. Loop diagram: (Chưa có thông tin triển khai) 3. Alarm trip setpoint: - DCS: Amo 100%, Uti 100%, Ure 100% - ESD: Amo 100%, Uti 100%, Ure 100% - PLC: 0% - MPS: 100% Trong tuần: - Cập nhật Alarm trip setpoint trên hệ thống PLC Nito (90%) Kế hoạch tuần tiếp theo: Triển khai rà soát cập nhật Alarm trip setpoint trên hệ thống PLC (tiếp tục) | J31: Đội HTĐK | K31: Không thay đổi trong tuần
B32: 9 | C32: Lắp đặt robot depalletizing | D32: Phase 2: Triển khai thực hiện | G32: 30/11/2026 | H32: 0.23 | I32: FS: Báo cáo chủ trương đã được phê duyệt (Đã thống nhất PA triển khai từ TGĐ: Lắp đặt 2 Robot/line và triển khai cho 1 line) Front end design: Xây dựng đầu bài dịch vụ (90%) (D/L: 15/05 đề xuất dời đến 29/05 do cần thêm thời gian để nhận góp ý từ NCC) Kế hoạch tiếp theo: - Làm rõ các điểm Tie-in về chuyên môn Điện - Họp để chốt đầu bài kỹ thuật (Tuần 22) Đã rà soát góp ý từ các đơn vị liên quan và điều chỉnh đầu bài kỹ thuật | J32: Phạm Thanh Quyền
B33: 10 | C33: Cải tạo hệ thống máng cáp | D33: Viết đầu bài kỹ thuật yêu cầu dịch dụ "Cung cấp vật tư, dịch vụ thi công gia cố máng cáp Điện - Điều khiển toàn Nhà máy". | G33: 30/05/2026 | H33: 0.96 | I33: Đang review | J33: Đội TBCH | K33: Không thay đổi trong tuần
B34: 11 | C34: Cải tạo tiếp địa TB ĐK | D34: Cải tạo tiếp địa thiết bị điều khiển xuống cọc sạch | G34: 46357 | H34: 0.35 | I34: - (23/1/2026) Họp thống nhất đối tượng cần cải tạo, thống nhất nhiệm vụ: 100% - Khảo sát vị trí bảng đồng chính: 100% (Cập nhật tuần 19) - Khảo sát vị trí bảng đồng nhánh: 20% (Cập nhật tuần 20) - Danh mục Van, JB cần cải tạo: 100% (Cập nhật tuần 12) - Danh mục TBĐ cần cải tạo: 100% (Cập nhật tuần 13) - Bốc tách khối lượng vật tư: 100% (Tuần 13) - Bốc tách khối lượng thi công: 20% (Cập nhật tuần 20) - Xây dựng PA kỹ thuật: 0% - Xây dựng PA thi công: 0% - Xây dựng đầu bài kỹ thuật: 0% - Tiến hành thi công: 0% - KH tuần tiếp theo KS vị trí bảng đồng nhánh (tt) | J34: Đội TBCH
B35: 12 | C35: Dịch vụ lắp mới 3 bộ đếm bao cho các line đóng bao Xưởng NPK | D35: Giám sát NCC thực hiện thi công lắp đặt hệ thống bộ đếm xưởng NPK Phối hợp Chạy thử, nghiệm thi | G35: 46127 | H35: 0.99 | I35: - Đã hoàn thành lắp đắt thiết bị. - Đã hoàn thành chạy thử 72h; - Đã lắp máy tính AI và đang cho học mẩu bao - NCC đã đào tạo, hướng dãn sử dụng hệ đếm đối chứng AI cho VH. - Do đếm AI còn đang sai nhiều nên NCC đã điều chỉnh ổn dịnh. - Đang phối hợp với NCC nghiệm thu gói dịch vụ. | K35: Không thay đổi trong tuần
B36: 13 | C36: Hệ thống Loa | D36: Nâng cấp hệ thống Loa nhà máy | G36: 46387 | H36: 0.25 | I36: - (19/1/2026) Làm rõ nhu cầu: 100% - Khảo sát, kiểm tra thực tế: 50% - Trao đổi NCC: 20% (NCC đã gửi báo giá sơ bộ, khảo sát thực tế) - Báo cáo B.GĐNM: 0% - Xây dựng đầu bài kỹ thuật: 0% - Xây dựng PA thi công: 0% - Thực hiện công việc: 0% - Hoàn thành họp đánh giá PA cùng các bên liên quan (Cập nhật tuần 20) - KH tuần tiếp theo tính toán số lượng lắp bổ sung tối đa dựa trên hiện trạng hệ thống
B37: 14 | C37: Dây tín hiệu tại các mương thoát nước | D37: Cải tạo dây tín hiệu dọc mương thoát nước. Làm gọn dây không gây cản trở dòng chảy | G37: 46357 | H37: 0.18 | I37: - Đã thực hiện mẫu đoạn dọc cổng A2 được B.GĐNM thông qua - Note các vị trí cải tạo gửi đầu mối P.HCQT - Khảo sát các tuyến cần âm cáp - Chuyển nội dung công việc thực hiện cải tạo về P.HCQT - KH tuần tiếp theo kháo sát tuyến âm cáp | K37: Không thay đổi trong tuần
B38: IV. CÔNG TÁC TPM
B39: Xử lý thẻ đỏ từ AM
B40: Tổng hạng mục | D40: 203
B41: Hoàn thành | D41: 187
B42: Tồn đọng | D42: 17
B43: Tỷ trọng hoàn thành | D43: =D41/D40 -> 0.92118227
...

Sheet 21
A2: NHÀ MÁY ĐẠM CÀ MAU | I2: CỘNG HÒA XÃ HỘI CHỦ NGHĨA VIỆT NAM
A3: XƯỞNG ĐIỀU KHIỂN | I3: Độc lập – Tự do – Hạnh phúc
H5: Cà Mau, ngày 22 tháng 05 năm 2026
H6: .
B7: BÁO CÁO TUẦN 21 VÀ KẾ HOẠCH TUẦN 22 NĂM 2026
B9: Xưởng Điều khiển báo cáo công việc thực hiện trong tuần như sau:
B10: I. CÔNG TÁC THỰC HIỆN BẢO DƯỠNG ĐỊNH KỲ
B11: TT | C11: Hạng mục công việc | D11: %WO thực hiện | E11: Tổng WO thực hiện trong tuần | F11: Tổng số WO đã thực hiện trong tháng | G11: Tổng số WO theo KH | H11: Tổng WO chưa thực hiện theo KH | I11: Lý do không thực hiện các WO trong tháng (nếu có) | J11: Đơn vị thực hiện | K11: Ghi chú | L11: TB đo | M11: TBCH | N11: HTĐK
B12: 1 | C12: Hạng mục thiết bị Điều khiển | D12: =F12/G12 -> 0.7940678 | E12: =O12 -> 258 | F12: =679+E12 -> 937 | G12: =O13 -> 1180 | H12: =G12-F12 -> 243 | J12: X. ĐK | L12: 113 | M12: 78 | N12: 67 | O12: =SUM(L12:N12) -> 258
B13: II. TÌNH HÌNH THỰC CÔNG VIỆC THEO KẾ HOẠCH NĂM | L13: 336 | M13: 608 | N13: 236 | O13: =SUM(L13:N13) -> 1180
B14: TT | C14: Hạng mục công việc | D14: Nội dung yêu cầu thực hiện | G14: Thời hạn hoàn thành | H14: Mức độ hoàn thành | I14: Tình hình thực hiện | J14: Đơn vị thực hiện | K14: Ghi chú | L14: TB đo | M14: TBCH | N14: HTĐK | O14: TCDK
B15: 1 | C15: Công tác STOP | D15: Khuyến khích CBCNV Xưởng tham gia chương trình | G15: Hàng tháng | H15: N/A | I15: - Số thẻ STOP trong tuần: ghi nhận 5 thẻ. - Số thẻ STOP tháng 05/2026: ghi nhận: 15 thẻ | J15: X. ĐK | L15: 0 | M15: 5 | N15: 0 | O15: 0 | P15: =SUM(L15:O15) -> 5
B16: 2 | C16: Công tác đào tạo năm 2026 | D16: Thực hiện đào tạo nội bộ theo kế hoạch trong năm 2026 | G16: 46387 | H16: =489/1126 -> 0.43428064 | I16: - Thực hiện trong tuần: 45 giờ. Tích lũy: 489/1126 giờ | J16: X. ĐK | L16: 16 | M16: 6 | N16: 8 | O16: 15 | P16: =SUM(L16:O16) -> 45
D17: Kế hoạch đào tạo bên ngoài | G17: 46387 | H17: N/A | I17: Chưa triển khai | J17: X. ĐK
B18: III. TÌNH HÌNH THỰC HIỆN CÁC HẠNG MỤC NÂNG CẤP, CẢI TIẾN, CẢI TẠO
B19: TT | C19: Hạng mục công việc | D19: Nội dung yêu cầu thực hiện | G19: Thời hạn hoàn thành | I19: Tình hình thực hiện | J19: Đơn vị thực hiện | K19: Ghi chú
B20: 1 | C20: Nghiên cứu triển khai lắp đặt hệ thống phun sơn tự động cho X.SP | D20: Nghiên cứu triển khai lắp đặt hệ thống phun sơn tự động cho X.SP V16 + Phun sơn tự động + Có thể linh hoạt di chuyển giữa các Line | G20: 46386 | H20: 0.92 | I20: - Hoàn thành lắp đặt hệ thống điều khiển, test máy phun sơn với nước đạt yêu cầu - Đang chờ đơn hàng sơn về để chạy test với sơn | J20: Đội TBCH | K20: Không thay đổi trong tuần
B21: 2 | C21: Cải tiến lại hệ thống robot NPK line A,B,C để gắp được bao 25kg | D21: Thực hiện các hạng mục công việc cần thiết để thực hiện cải tiến 3 line robot NPK A,B,C cho bao 25kg | G21: 46386 | H21: 0.95 | I21: - Hoàn thành lập trình tọa độ và cấu hình lớp bao cho loại bao 25kg - Hoàn thành chạy thử và bàn giao vận hành Line C - Line B chưa test được do không đóng bao 25kg | J21: Đội TBCH | K21: Không thay đổi trong tuần
B22: 3 | C22: Nâng cấp hệ thống F&G | D22: Phase 2: Triển khai thực hiện | G22: 30/09/2026 | H22: 0.43 | I22: FS: Báo cáo chủ trương đã được phê duyệt Front end and detail design: - Tình hình các đơn hàng: ĐH 1: Cung cấp vật tư đầu dò phục vụ lắp bổ sung đầu dò gas detector: KHMS (Điều chỉnh lại spec và trình lại YCMS vào tuần 22) ĐH 2: Cung cấp vật tư thiết bị hệ thống phục vụ lắp bổ sung đầu dò gas detector: HSMCG ĐH 3: Cung cấp dịch vụ thi công hạ tầng, lắp đặt thiết bị gas detector: HSMCG - Thiết kế kỹ thuật (100%) - Xây dựng phương án triển khai scope PVCFC (83%) (D/L: 30/05) | J22: Phạm Thanh Quyền
B23: 4 | C23: Khắc phục tồn động hệ thống pccc từ Đoàn thanh tra Bộ Công an về công tác PCCC | D23: Tòa nhà khối bảo dưỡng: Rà soát lại các thiết kế hệ thống báo cháy theo thẩm duyệt: hệ thống nào có thiết kế điện trở cuối kênh hay không có điện trở cuối kênh phải đảm bảo đúng thiết kế. Phòng ATMT lập WR, X.ĐK thực hiện tại tòa nhà khối bảo dưỡng | G23: 30/03/2026 | H23: 100% | I23: Hoàn thành khắc phục các điểm sai khác bản vẽ thẩm duyệt Đã hoàn thành nghiệm thu với P.AT - P.ATMT kiểm tra lắp đặt điện trở cuối, điện trở cuối đã được lắp đặt theo đúng bản vẽ thẩm duyệt - P.ATMT tháo thiết bị bất kỳ tại các zone, tủ báo cháy hiển thị lỗi hở mạch zone đó. | J23: Tổ TBHTPC
D24: Các đầu báo cháy nằm cách trần nhà >0.3m. P.AT lập WR sau khi khảo sát và X.ĐK lên kế hoạch thực hiện | G24: 30/03/2026 | H24: 0.76 | I24: - Tích lũy thực hiện di dời đầu dò không cần giàn giáo: 35/35 đầu dò - Tích lũy thực hiện di dời có giàn giáo: 75/82 đầu dò - Tích lũy thực hiện lắp mới có giàn giáo: 21/21 đầu dò | J24: Tổ TBHTPC
D25: Mua sắm bổ sung các thiết bị test báo cháy phù hợp. P.ATMT lập kế hoạch mua sắm | G25: 30/03/2026 | H25: 0.85 | I25: Đã đưa vào kế hoạch mua sắm 2026 Đã lập danh mục đưa vào YCMS CCDC và đã gửi đầu mối xưởng triển khai mua sắm Kế hoạch tiếp theo: theo dõi mua sắm | J25: Tổ TBHTPC
B26: 5 | C26: Hệ thống FA lắp mới | D26: Phối hợp P.AT khảo sát các thiết bị báo cháy lắp mới cần kết nối về hệ thống trung tâm tại Nhà máy với bảng MIMIC | G26: 30/12/2025 | H26: 1 | I26: Hoàn thành phối hợp P.AT khảo sát xác định các khu vực chưa kết nối hệ thống Fire Alarm về hệ thống trung tâm và đưa ra yêu cầu có thứ tự ưu tiên. | J26: Tổ TBHTPC
D27: X. ĐK đánh giá tính khả thi về kỹ thuật và chi phí sơ bộ để thực hiện kết nối hệ thống Fire Alarm theo thứ tự ưu tiên của P. ATMT. | G27: 30/12/2025 | H27: 1 | I27: Hoàn thành bốc tách vật tư và chi phí thực hiện, đã trình bày trước LĐX Xưởng và được thông qua. Hoàn thành xin ý kiến LĐNM và đã triển khai YCMS VT | J27: Tổ TBHTPC
D28: Thiết kế hệ thống MIMIC phải đồng bộ với việc kết nối hệ thống Fire Alarm và F&G. | G28: 30/03/2026 | H28: 0.26 | I28: Hoàn thành cập nhật bản vẻ CAD và graphic F&G Đang liên hệ các nhà cung cấp đề thiết kế bản vẽ Hoàn thành vẽ graphic MIMIC PANEL mới tại máy tính FGS Đã xin ý kiến LĐX về các giải pháp: Gợi ý về bảng MIMIC mới: tìm hiểu về bảng MIMIC hiển thị bằng màn hình LED. Cập nhật bản vẽ CAD và graphic máy tính F&G: Hoàn thành Trong tuần: - Soạn phương án thực hiện kết nối các hệ thống báo cháy lắp mới: 71% Tuần sau: Soạn phương án thực hiện kết nối các hệ thống báo cháy lắp mới. Trao đổi với p.AT về giải pháp bảng MIMIC | J28: Tổ TBHTPC
B29: 6 | C29: Hệ thống PLC K04421 | D29: Nghiên cứu phương án lấy tín hiệu từ Trident K04421 về HMI Siemens PLC | G29: 01/09/2026 | H29: 0.6 | I29: Đã hoàn thành: - Thực hiện cấu hình thử nghiệm trên phần mềm WinccFlexible lấy dữ liệu qua đường truyền Modbus TCP/IP - Thực hiện cấu hình thử nghiệm trên phần mềm Tristation truyền Modbus TCP/IP đến thiết bị khác - Dùng phần mềm Modbus Slave để kiểm tra kết nối Modbus TCP/IP với Wincc Flexible - Đã trao đổi với Schneider về các phương án truyền dữ liệu giữa HMI Siemens và Trident, Schneider cần kiểm tra thêm Version V3.1 có hỗ trợ Modbus TCP/IP không. - Mô phỏng kết nối lấy dữ liệu tử Trident về WinCC Classic (PCS 7) qua DDE, trong trường hợp cần thiết có thế lấy dữ liệu từ Trident K04421 về HMI K04441 (Do HMI K04421 không hỗ trợ DDE, K04441 có thể kết nối lấy dữ liệu từ Trident qua DDE). - Nhắc Schneider kiểm tra thông tin Version V3.1 có hỗ trợ Modbus TCP/IP không để lên p/a thực hiện kết nối Trident với HMI trong BDTT 2026 - P. KTBD đã y/c Schneider kiểm tra thông tin Version V3.1 có hỗ trợ Modbus TCP/IP không để lên p/a thực hiện kết nối Trident với HMI trong BDTT 2026 - Lắp đặt xong phần cứng Trident để thử nghiệm truyền thông giữa HMI và Trident - Test kiểm tra xong kết nối modbus TCP/IP giữa Trident và HMI Siemens Trong tuần: Kiểm tra truyền giá trị giữa HMI và Trident, các tín hiệu truyền tốt tuy nhiên còn tín hiệu Setpoint giá trị Real từ HMI sang Trident chưa thực hiện được. Tuần sau: - Nghiên cứu truyền giá trị Setpoint Real từ HMI sang Trident - Soạn thảo phương án thực hiện trong BDTT 2026 | J29: Trịnh Văn Kiều | K29: Không thay đổi trong tuần
B30: 7 | C30: Cập nhật các tài liệu loop diagram, Interlock Logic diagram, Alarm trip setpoint | D30: Phối hợp P.KTBD và các Xưởng VH cập nhật các tài liệu Loop diagram, Interlock Logic diagram, Alarm trip setpoint | G30: N/A | H30: 0.52 | I30: 1. Interlock Logic diagram: - DCS: 0% - ESD: 0% - PLC: 0% - MPS: 100% 2. Loop diagram: (Chưa có thông tin triển khai) 3. Alarm trip setpoint: - DCS: Amo 100%, Uti 100%, Ure 100% - ESD: Amo 100%, Uti 100%, Ure 100% - PLC: 0% - MPS: 100% Trong tuần: - Cập nhật Alarm trip setpoint trên hệ thống PLC Nito (90%) Kế hoạch tuần tiếp theo: Triển khai rà soát cập nhật Alarm trip setpoint trên hệ thống PLC (tiếp tục) | J30: Đội HTĐK | K30: Không thay đổi trong tuần
B31: 8 | C31: Lắp đặt robot depalletizing | D31: Phase 2: Triển khai thực hiện | G31: 30/11/2026 | H31: 0.23 | I31: FS: Báo cáo chủ trương đã được phê duyệt (Đã thống nhất PA triển khai từ TGĐ: Lắp đặt 2 Robot/line và triển khai cho 1 line) Front end design: Xây dựng đầu bài dịch vụ (90%) (D/L: 15/05 đề xuất dời đến 29/05 do cần thêm thời gian để nhận góp ý từ NCC) Kế hoạch tiếp theo: Họp để chốt đầu bài kỹ thuật (Tuần 22) và trình YCDV | J31: Phạm Thanh Quyền
B32: 9 | C32: Cải tạo hệ thống máng cáp | D32: Viết đầu bài kỹ thuật yêu cầu dịch dụ "Cung cấp vật tư, dịch vụ thi công gia cố máng cáp Điện - Điều khiển toàn Nhà máy". | G32: 30/05/2026 | H32: 0.96 | I32: Đang review | J32: Đội TBCH | K32: Không thay đổi trong tuần
B33: 10 | C33: Cải tạo tiếp địa TB ĐK | D33: Cải tạo tiếp địa thiết bị điều khiển xuống cọc sạch | G33: 46357 | H33: 0.35 | I33: - (23/1/2026) Họp thống nhất đối tượng cần cải tạo, thống nhất nhiệm vụ: 100% - Khảo sát vị trí bảng đồng chính: 100% (Cập nhật tuần 19) - Khảo sát vị trí bảng đồng nhánh: 20% (Cập nhật tuần 20) - Danh mục Van, JB cần cải tạo: 100% (Cập nhật tuần 12) - Danh mục TBĐ cần cải tạo: 100% (Cập nhật tuần 13) - Bốc tách khối lượng vật tư: 100% (Tuần 13) - Bốc tách khối lượng thi công: 20% (Cập nhật tuần 20) - Xây dựng PA kỹ thuật: 0% - Xây dựng PA thi công: 0% - Xây dựng đầu bài kỹ thuật: 0% - Tiến hành thi công: 0% - KH tuần tiếp theo KS vị trí bảng đồng nhánh (tt) | J33: Đội TBCH | K33: Không thay đổi trong tuần
B34: 11 | C34: Dịch vụ lắp mới 3 bộ đếm bao cho các line đóng bao Xưởng NPK | D34: Giám sát NCC thực hiện thi công lắp đặt hệ thống bộ đếm xưởng NPK Phối hợp Chạy thử, nghiệm thu | G34: 46127 | H34: 1 | I34: - Đã hoàn thành lắp đắt thiết bị. - Đã hoàn thành chạy thử 72h; - Đã lắp máy tính AI và đang cho học mẩu bao - NCC đã đào tạo, hướng dãn sử dụng hệ đếm đối chứng AI cho VH. - Do đếm AI còn đang sai nhiều nên NCC đã điều chỉnh ổn dịnh. - Công việc đã hoàn thành, chờ ký nghiệm thu.
B35: 12 | C35: Hệ thống Loa | D35: Nâng cấp hệ thống Loa nhà máy | G35: 46387 | H35: 0.25 | I35: - (19/1/2026) Làm rõ nhu cầu: 100% - Khảo sát, kiểm tra thực tế: 50% - Trao đổi NCC: 20% (NCC đã gửi báo giá sơ bộ, khảo sát thực tế) - Báo cáo B.GĐNM: 0% - Xây dựng đầu bài kỹ thuật: 0% - Xây dựng PA thi công: 0% - Thực hiện công việc: 0% - Hoàn thành họp đánh giá PA cùng các bên liên quan (Cập nhật tuần 20) - KH tuần tiếp theo tính toán số lượng lắp bổ sung tối đa dựa trên hiện trạng hệ thống (tt)
B36: 13 | C36: Dây tín hiệu tại các mương thoát nước | D36: Cải tạo dây tín hiệu dọc mương thoát nước. Làm gọn dây không gây cản trở dòng chảy | G36: 46357 | H36: 0.18 | I36: - Đã thực hiện mẫu đoạn dọc cổng A2 được B.GĐNM thông qua - Note các vị trí cải tạo gửi đầu mối P.HCQT - Khảo sát các tuyến cần âm cáp - Chuyển nội dung công việc thực hiện cải tạo về P.HCQT - KH tuần tiếp theo kháo sát tuyến âm cáp | K36: Không thay đổi trong tuần
B37: IV. CÔNG TÁC TPM
B38: Xử lý thẻ đỏ từ AM
B39: Tổng hạng mục | D39: 203
B40: Hoàn thành | D40: 187
B41: Tồn đọng | D41: 17
B42: Tỷ trọng hoàn thành | D42: =D40/D39 -> 0.92118227
B43: Phát sinh trong tuần | D43: 0
...

Sheet Dashboard
B122: STT | C122: Hạng mục công việc | I122: Tình trạng sự cố | M122: Nội dung thực hiện xử lý
B123: 1 | C123: =BC_LĐNM!J2 -> Camera 44/45/46/47 | I123: =BC_LĐNM!K2 -> An Toàn báoCamera 44/45/46/47 khu vực phía sau nhà đóng bao NPK | M123: =BC_LĐNM!L2 -> Nguyên nhân : Không cón tín hiệu truyền thông quang. Thực hiện: Kiểm tra các tủ box đấu nối thì phát hiện không có tín hiệu truyền thông quang, chưa rõ nguyên nhân. An Toàn đã thông tin nhà thầu kiểm tra lại Kết quả: Hiện camera chưa lên hình, An Toàn đã thông tin nhà thầu kiểm tra lại .
B124: 2 | C124: =BC_LĐNM!J3 -> 06PI-2258 | I124: =BC_LĐNM!K3 -> Giá trị đo sai (35 bar so với giá trị VH bình thường là 40 bar) . | M124: =BC_LĐNM!L3 -> Nguyên nhân : Chưa biết nguyên nhân . Thực hiện: Quan sát thấy thiết bị đo sai với thực tế, tiến hành thực hiện theo y/c VH tháo 06PI-2257 sang lắp thay thế cho 06PI-2258. Hiện tại 06PI-2258 đem về phòng trực ca, chuyển ca ngày 18/5 đầu tuần mang sang Tổ HC kiểm tra lại. Kết quả: Chuyển ca ngày 18/5 đầu tuần mang sang Tổ HC kiểm tra lại.
B125: 3 | C125: =BC_LĐNM!J4 -> 48XS-0048A | I125: =BC_LĐNM!K4 -> Hỏng switch lệch băng | M125: =BC_LĐNM!L4 -> Nguyên nhân: Hỏng switch lệch băng Thực hiện: Kiểm tra băng tải hỏng switch lệch băng, thực hiện nhận vật tư mới thay thế, tuy nhiên do nhu cầu xuất hàng ĐVCQ chưa dừng được, chuyển ca sau phối hợp xử lý Kết quả: Đã nhận thiết bị mới về phòng ca, chuyển ca sau thực hiện thay thế khi có cơ hội
B126: 4 | C126: =BC_LĐNM!J5 -> 0 | I126: =BC_LĐNM!K5 -> 0 | M126: =BC_LĐNM!L5 -> 0
B127: 5 | C127: =BC_LĐNM!J6 -> 0 | I127: =BC_LĐNM!K6 -> 0 | M127: =BC_LĐNM!L6 -> 0
B128: 6 | C128: =BC_LĐNM!J7 -> 0 | I128: =BC_LĐNM!K7 -> 0 | M128: =BC_LĐNM!L7 -> 0
B129: 7 | C129: =BC_LĐNM!J8 -> 0 | I129: =BC_LĐNM!K8 -> 0 | M129: =BC_LĐNM!L8 -> 0
B130: =ROW()-89 -> 41 | C130: =BC_LĐNM!J9 -> 0 | I130: =BC_LĐNM!K9 -> 0 | M130: =BC_LĐNM!L9 -> 0
B131: =ROW()-89 -> 42 | C131: =BC_LĐNM!J10 -> 0 | I131: =BC_LĐNM!K10 -> 0 | M131: =BC_LĐNM!L10 -> 0
A132: i | B132: =ROW()-89 -> 43 | C132: =BC_LĐNM!J11 -> 0 | I132: =BC_LĐNM!K11 -> 0 | M132: =BC_LĐNM!L11 -> 0
B133: =ROW()-89 -> 44 | C133: =BC_LĐNM!J12 -> 0 | I133: =BC_LĐNM!K12 -> 0 | M133: =BC_LĐNM!L12 -> 0
B134: =ROW()-89 -> 45 | C134: =BC_LĐNM!J13 -> 0 | I134: =BC_LĐNM!K13 -> 0 | M134: =BC_LĐNM!L13 -> 0
B135: =ROW()-89 -> 46 | C135: =BC_LĐNM!J14 -> 0 | I135: =BC_LĐNM!K14 -> 0 | M135: =BC_LĐNM!L14 -> 0
B136: =ROW()-89 -> 47 | C136: =BC_LĐNM!J15 -> 0 | I136: =BC_LĐNM!K15 -> 0 | M136: =BC_LĐNM!L15 -> 0
B137: =ROW()-89 -> 48 | C137: =BC_LĐNM!J16 -> 0 | I137: =BC_LĐNM!K16 -> 0 | M137: =BC_LĐNM!L16 -> 0
B139: STT | C139: Hạng mục công việc | I139: Tình trạng sự cố | M139: Nội dung thực hiện xử lý
B140: 1 | C140: =DATA_BC_TUAN!T2 -> 48XS-0044A | I140: =DATA_BC_TUAN!U2 -> Hỏng switch lệch băng | M140: =DATA_BC_TUAN!V2 -> Nguyên nhân: Thực hiện theo yêu cầu Thực hiện: Gia cố lại Switch theo yêu cầu. Kết quả: Đã thực hiện theo yêu cầu, bàn giao ĐVCQ
B141: 2 | C141: =DATA_BC_TUAN!T3 -> V48016D | I141: =DATA_BC_TUAN!U3 -> Hỏng switch lệch băng (giao ca) | M141: =DATA_BC_TUAN!V3 -> Nguyên nhân: Hỏng switch lệch băng Thực hiện: Ca ngày 18/05/2025: Kiểm tra băng tải hỏng switch lệch băng, thực hiện nhận vật tư mới thay thế, tuy nhiên do nhu cầu xuất hàng ĐVCQ chưa dừng được, chuyển ca sau phối hợp xử lý. Ca ngày 19/05/2025: Sau khi kiểm tra thiết bị đang hoạt động tốt, bàn giao ĐVVH theo dõi thêm. Kết quả: Thiết bị hoạt động bình thường. Bàn giao ĐVVH
B142: 3 | C142: =DATA_BC_TUAN!T4 -> V48016A 48XS-0048A | I142: =DATA_BC_TUAN!U4 -> Hỏng switch lệch băng (giao ca) | M142: =DATA_BC_TUAN!V4 -> Nguyên nhân: Hỏng switch lệch băng Thực hiện: Ca ngày 18/05/2025: Kiểm tra băng tải hỏng switch lệch băng, thực hiện nhận vật tư mới thay thế, tuy nhiên do nhu cầu xuất hàng ĐVCQ chưa dừng được, chuyển ca sau phối hợp xử. Ca ngày 19/05/2025: Sau khi VH dừng băng tải, tiến hành thay mới từ thiết bị, đưa vào hoạt động. Kết quả: Thiết bị hoạt động bình thường. Bàn giao ĐVVH
B143: 4 | C143: =DATA_BC_TUAN!T5 -> 04PDT-3057 | I143: =DATA_BC_TUAN!U5 -> Rò khớp nối (giao ca) | M143: =DATA_BC_TUAN!V5 -> Nguyên nhân: Chưa rõ nguyên nhân Thực hiện: Ca ngày 18/05/2026: Kiểm tra phát hiện rò khớp nối, thực hiện siết không hết rò, thiết bị không tháo được do vướng mặt bích thiết bị đo áp, chuyển ca sau tìm giải pháp xử lý. Ca Ngày 19/05/2026: Tiếp tục kiểm tra siết rò đưa thiết bị vào hoạt động. Kết quả: Thiết bị hoạt động bình thường. Bàn giao ĐVCQ
B144: 5 | C144: =DATA_BC_TUAN!T6 -> 40PI-2013 | I144: =DATA_BC_TUAN!U6 -> Lắp lại theo yêu cầu | M144: =DATA_BC_TUAN!V6 -> Nguyên nhân: Thực hiện theo yêu cầu VH Thực hiện: Kiểm tra thực hiện lắp PI theo yêu cầu sau khi VH thực hiện xong công việc Kết quả: Thiết bị đã lắp lại theo yêu cầu, bàn giao ĐVCQ.
B145: 6 | C145: =DATA_BC_TUAN!T7 -> 06VT-2123B | I145: =DATA_BC_TUAN!U7 -> VH báo giá trị độ rung cao 0.8-1.2 mm/s trong khi pump P06101B đang dừng | M145: =DATA_BC_TUAN!V7 -> Nguyên nhân: Barrier lỗi Thực hiện: Ngày 19/5 Kiểm tra đầu dò độ rung cao hơn so với các đầu dò khác 1,8xxmm/s mặc dù bơm đang dừng. Kiểm tra lịch sử đầu dò và barrier mới thay trong BDTT 2025, nhưng dây extension chưa thay, đánh giá trao đổi cùng planner và tổ chuyên môn lấy vật tư dây extension thay thế để loại trừ. Giá trị đã về 0,8xx mm/s sau khi thay thế. Ngày 20/5 Đánh giá chỉ còn barrier chưa thay khả năng barrier là cao. Nhận thay barier mới thay thế. Sau khi thay giá trị bộ rung về 0.06 mm/s. Kết quả: Thiết bị hoạt động bình thường.
B146: 7 | C146: =DATA_BC_TUAN!T8 -> 04PV-4251 CO2 Chiller | I146: =DATA_BC_TUAN!U8 -> Valve bị kẹt 0~5% | M146: =DATA_BC_TUAN!V8 -> Nguyên nhân: Travel lệch Thực hiện: Kiểm tra MV= 0~5% valve không di chuyển ty, output posit không có, tuy nhiên từ ~4.5% thì output posit có tác động và ti valve di chuyển. Dùng Hart kiểm tra thì travel lệch 5.1% ở 3.99mA. Tiến hành calib lại travel, valve hoạt động đúng, đáp ứng bình thường, bàn giao VH. Kết quả: Valve đáp ứng bình thường, bàn giao VH
B147: 8 | C147: =DATA_BC_TUAN!T9 -> 0 | I147: =DATA_BC_TUAN!U9 -> 0 | M147: =DATA_BC_TUAN!V9 -> 0
B148: 9 | C148: =DATA_BC_TUAN!T10 -> 0 | I148: =DATA_BC_TUAN!U10 -> 0 | M148: =DATA_BC_TUAN!V10 -> 0
B149: 10 | C149: =DATA_BC_TUAN!T11 -> 0 | I149: =DATA_BC_TUAN!U11 -> 0 | M149: =DATA_BC_TUAN!V11 -> 0
B150: 11 | C150: =DATA_BC_TUAN!T12 -> 0 | I150: =DATA_BC_TUAN!U12 -> 0 | M150: =DATA_BC_TUAN!V12 -> 0
B151: 12 | C151: =DATA_BC_TUAN!T13 -> 0 | I151: =DATA_BC_TUAN!U13 -> 0 | M151: =DATA_BC_TUAN!V13 -> 0
... B154: 15 | C154: =DATA_BC_TUAN!T16 -> 0 | I154: =DATA_BC_TUAN!U16 -> 0 | M154: =DATA_BC_TUAN!V16 -> 0
B380: STT | C380: Hạng mục công việc | AH380: Thời gian hoàn thành
B381: 1 | C381: ='21'!C173 -> Thực hiện công tác BDĐK theo kế hoạch tháng 05/2026 | AH381: ='21'!K173 -> 46173
B382: 2 | C382: ='21'!C174 -> Tiếp tục thực hiện các hạng mục công việc tồn đọng ở trên | AH382: ='21'!K174 -> N/A
B383: 3 | C383: ='21'!C175 -> Tiếp tục triển khai đơn hàng mua sắm 2026 | AH383: ='21'!K175 -> N/A
B384: 4 | C384: ='21'!C176 -> Triển khai thực hiện các cải tiến/cải tạo/dịch vụ theo kế hoạch năm 2026 | AH384: ='21'!K176 -> N/A
B385: 5 | C385: ='21'!C177 -> Quản trị rủi ro thiết bị hệ thống điều khiển | AH385: ='21'!K177 -> 46171
B386: 6 | C386: ='21'!C178 -> 0 | AH386: ='21'!K178 -> 0
B387: 7 | C387: ='21'!C179 -> 0 | AH387: ='21'!K179 -> 0
B388: 8 | C388: ='21'!C180 -> 0 | AH388: ='21'!K180 -> 0
B389: 9 | C389: ='21'!C181 -> 0 | AH389: ='21'!K181 -> 0
...

Sheet Data
F2: Tồn đọng (HM)
B3: T5 | C3: ='21'!G12 -> 1180 | D3: ='21'!F12 -> 937 | E3: =D3/C3 -> 0.7940678 | F3: =C3-D3 -> 243
H5: Ngày còn lại trong tháng
A6: BD ĐK | B6: Tháng | C6: Kế hoạch | D6: Thực hiện | E6: % HT | F6: Tồn đọng (HM) | H6: =EOMONTH(TODAY(),0)-TODAY()+1 -> 10
B7: T1 | C7: 1759 | D7: 1695 | E7: =D7/C7 -> 0.96361569 | F7: =C7-D7 -> 64
B8: T2 | C8: 1077 | D8: 1077 | E8: =D8/C8 -> 1 | F8: =C8-D8 -> 0
B9: T3 | C9: 1394 | D9: 1341 | E9: =D9/C9 -> 0.96197991 | F9: =C9-D9 -> 53
B10: T4 | C10: 1424 | D10: 1399 | E10: =D10/C10 -> 0.98244382 | F10: =C10-D10 -> 25
B11: T5 | C11: =C3 -> 1180 | D11: =D3 -> 937 | E11: =D11/C11 -> 0.7940678 | F11: =C11-D11 -> 243
B12: T6 | C12: 0 | D12: 0 | E12: =D12/C12 -> #DIV/0! | F12: =C12-D12 -> 0
B13: T7 | C13: 0 | D13: 0 | E13: =D13/C13 -> #DIV/0! | F13: =C13-D13 -> 0
B14: T8 | C14: 0 | D14: 0 | E14: =D14/C14 -> #DIV/0! | F14: =C14-D14 -> 0
B15: T9 | C15: 0 | D15: 0 | E15: =D15/C15 -> #DIV/0! | F15: =C15-D15 -> 0
B16: T10 | C16: 0 | D16: 0 | E16: =D16/C16 -> #DIV/0! | F16: =C16-D16 -> 0
B17: T11 | C17: 0 | D17: 0 | E17: =D17/C17 -> #DIV/0! | F17: =C17-D17 -> 0
B18: T12 | C18: 0 | D18: 0 | E18: =D18/C18 -> #DIV/0! | F18: =C18-D18 -> 0
C19: =SUM(C7:C18) -> 6834 | D19: =SUM(D7:D18) -> 6449 | E19: =D19/C19 -> 0.94366403 | F19: =C19-D19 -> 385
A22: Tháng 5 | B22: Tuần 19 | D22: 333
B23: Tuần 20 | D23: 346
B24: Tuần 21 | D24: ='21'!E12 -> 258
B25: Tuần 22 | D25: 0
D27: Yêu cầu thực hiện | E27: Đạt | F27: Chưa Đạt | G27: Theo dõi
A28: SCĐX | B28: Tuần | C28: 21 | D28: =COUNTIF(BC_LĐNM!B2:B475,"*") -> 64 | E28: =D28-(F28+G28) -> 61 | F28: =BC_LĐNM!K1 -> 3 | G28: =COUNTIFS(BC_LĐNM!D:D,C28,BC_LĐNM!E:E,"Theo dõi*") -> 0 | H28: =E28/D28 -> 0.953125
D29: Hạng mục | E29: Đạt | F29: % HT
A30: T5 | B30: Tuần 19 | D30: 100 | E30: 92 | F30: =E30/D30 -> 0.92
B31: Tuần 20 | D31: 71 | E31: 68 | F31: =E31/D31 -> 0.95774648
B32: Tuần 21 | D32: 64 | E32: 61 | F32: =E32/D32 -> 0.953125
B33: Tuần 22 | F33: =E33/D33 -> #DIV/0!
A34: Lũy kế năm
B35: Tháng | C35: Hạng mục | D35: Đạt | E35: % HT
B36: T1 | C36: 230 | D36: 224 | E36: =(D36+G36)/C36 -> 0.97391304
B37: T2 | C37: 192 | D37: 174 | E37: =(D37+G37)/C37 -> 0.90625
B38: T3 | C38: 326 | D38: 311 | E38: =IFERROR((D38+G38)/C38,"") -> 0.95398773
B39: T4 | C39: 356 | D39: 335 | E39: =IFERROR((D39+G39)/C39,"") -> 0.94101124
B40: T5 | C40: =SUM(D30:D33) -> 235 | D40: =SUM(E30:E33) -> 221 | E40: =IFERROR((D40+G40)/C40,"") -> 0.94042553
B41: T6 | C41: 0 | D41: 0 | E41: =IFERROR((D41+G41)/C41,"")
B42: T7 | C42: 0 | D42: 0 | E42: =IFERROR((D42+G42)/C42,"")
B43: T8 | C43: 0 | D43: 0 | E43: =IFERROR((D43+G43)/C43,"")
B44: T9 | C44: 0 | D44: 0 | E44: =IFERROR((D44+G44)/C44,"")
B45: T10 | C45: 0 | D45: 0 | E45: =IFERROR((D45+G45)/C45,"")
...

Sheet DATA_BC_TUAN
A1: STT | B1: HANG_MUC | C1: Số WR | D1: GPLV | E1: CUM_CONG_NGHE | F1: NHOM_CHUYEN_MON | G1: THONG_TIN_TU_VH | H1: LOAI_HINH_CV | I1: NOI_DUNG_THUC_HIEN | J1: NGUYEN_NHAN | K1: NGUYEN_NHAN_GOC | L1: PHAN_LOAI_NGUYEN_NHAN | M1: TUAN | N1: NGAY_THUC_HIEN | O1: MAN_HOURS | P1: KQ | Q1: TO_THUC_HIEN | R1: GC | T1: 21 | U1: =COUNTIF(T:T,"*") -> 7 | V1: Tồn đọng đã XL
A2: 1 | B2: V48016B | C2: N/A | D2: 6280/LVC | E2: SAN PHAM | F2: DK-SAN PHAM | G2: Đứt dây safety rope | H2: SCĐX | I2: Nguyên nhân: Dây safety rope mục đứt thời gian sử dụng lâu. Thực hiện: Kiểm tra dây safety rope đã được nối nhiều đoạn. Mục không đảm bảo an toàn. Lấy dây mới thay thế. Kết quả: Dây đẫ được thay mới | M2: 1 | N2: 46018 | O2: 1 | P2: Đạt | Q2: Kíp IV | R2: Kíp IV Ca Ngày | T2: {=_xlfn._xlws.FILTER(B:B,(H:H="XLTĐ")*(M:M=T1)*(P:P="Đạt"))} -> 48XS-0044A | U2: {=_xlfn._xlws.FILTER(G:G,(H:H="XLTĐ")*(M:M=T1)*(P:P="Đạt"))} -> Hỏng switch lệch băng | V2: {=_xlfn._xlws.FILTER(I:I,(H:H="XLTĐ")*(M:M=T1)*(P:P="Đạt"))} -> Nguyên nhân: Thực hiện theo yêu cầu Thực hiện: Gia cố lại Switch theo yêu cầu. Kết quả: Đã thực hiện theo yêu cầu, bàn giao ĐVCQ
A3: =A2+1 -> 2 | B3: L48002C | C3: N/A | D3: 6280/LVC | E3: SAN PHAM | F3: DK-SAN PHAM | G3: robot xếp bao không chuẩn làm đổ bao trên pallet | H3: SCĐX | I3: Nguyên nhân: 2 ngàm kẹp bao đóng mở không đều Thực hiện: Kiểm tra phát hiện 2 ngàm kẹp bao đóng mở không đều nên khi xếp bao vào pallet không chuẩn vị trí trên pallet làm đổ bao. Đã chỉnh lại lưu lượng khí vào piston đều nhau. Kết quả: Robot đã xếp bao chuẩn. | M3: 1 | N3: 46018 | O3: 1 | P3: Đạt | Q3: Kíp IV | R3: Kíp IV Ca Ngày | T3: V48016D | U3: Hỏng switch lệch băng (giao ca) | V3: Nguyên nhân: Hỏng switch lệch băng Thực hiện: Ca ngày 18/05/2025: Kiểm tra băng tải hỏng switch lệch băng, thực hiện nhận vật tư mới thay thế, tuy nhiên do nhu cầu xuất hàng ĐVCQ chưa dừng được, chuyển ca sau phối hợp xử lý. Ca ngày 19/05/2025: Sau khi kiểm tra thiết bị đang hoạt động tốt, bàn giao ĐVVH theo dõi thêm. Kết quả: Thiết bị hoạt động bình thường. Bàn giao ĐVVH
A4: =A3+1 -> 3 | B4: W48001B | C4: N/A | D4: 6280/LVC | E4: SAN PHAM | F4: DK-SAN PHAM | G4: VH báo cân đối chứng trip liên tục mặc dù bao đủ ký ( tồn đọng) | H4: SCĐX | I4: Nguyên nhân: Chưa tìm nguyên nhân gốc Thực hiện: Đêm 26/12 Kiểm tra cân đối chứng bao đi qua thì dừng, cân lại bao vẫn đủ ký. Calib lại cân, cân chỉnh đầu dò tuy nhiên vẫn dừng không có lý do. Tạm thời thay đầu cân W100 spare, cài đặt lại thông số đầu cân, zero và calib lại cân, đưa cân vào hoạt động. Ngày 27/12 Thay đầu cân từ line B NPK sang cài lại thông số đầu cân đóng bao được buổi sáng. Chiều lại lỗi tiếp, kiểm tra sensor, giá trị cài đều bình thường nhưng cân vẫn trip báo sai ký. Kéo bao đạm cân lại thì đúng ký. Vẫn chưa tìm ra nguyên nhân chuyển ca sau xử lý tiếp Kết quả: Cân đối chứng vẫn còn sai | M4: 1 | N4: 46018 | O4: 5 | P4: Chưa đạt | Q4: Kíp IV | R4: Kíp IV Ca Ngày | T4: V48016A 48XS-0048A | U4: Hỏng switch lệch băng (giao ca) | V4: Nguyên nhân: Hỏng switch lệch băng Thực hiện: Ca ngày 18/05/2025: Kiểm tra băng tải hỏng switch lệch băng, thực hiện nhận vật tư mới thay thế, tuy nhiên do nhu cầu xuất hàng ĐVCQ chưa dừng được, chuyển ca sau phối hợp xử. Ca ngày 19/05/2025: Sau khi VH dừng băng tải, tiến hành thay mới từ thiết bị, đưa vào hoạt động. Kết quả: Thiết bị hoạt động bình thường. Bàn giao ĐVVH
A5: =A4+1 -> 4 | B5: 27LT-0001 | C5: N/A | D5: 6149/LCV | E5: UTILITY | F5: DK-AMLL | G5: Giá trị dao động. | H5: SCĐX | I5: Nguyên nhân: Do lắp đặt gần thành bể nghi nhiễu sóng rada Thực hiện: Kiểm tra vị trí lắp đặt transmitter rada gần thành bể nghi nhiễn sóng rada. Gia công vị trí pát bắt transmitter mới di dời điểm đo phù hợp. Kết quả: Transmitter đã hết dao động | M5: 1 | N5: 46018 | O5: 2 | P5: Đạt | Q5: Kíp IV | R5: Kíp IV Ca Ngày | T5: 04PDT-3057 | U5: Rò khớp nối (giao ca) | V5: Nguyên nhân: Chưa rõ nguyên nhân Thực hiện: Ca ngày 18/05/2026: Kiểm tra phát hiện rò khớp nối, thực hiện siết không hết rò, thiết bị không tháo được do vướng mặt bích thiết bị đo áp, chuyển ca sau tìm giải pháp xử lý. Ca Ngày 19/05/2026: Tiếp tục kiểm tra siết rò đưa thiết bị vào hoạt động. Kết quả: Thiết bị hoạt động bình thường. Bàn giao ĐVCQ
A6: =A5+1 -> 5 | B6: V48005 | C6: N/A | D6: 06281/LVC | E6: SAN PHAM | F6: DK-SAN PHAM | G6: Cào đạm bị gãy switch toạ độ số 75 (tồn đọng) | H6: SCĐX | I6: Nguyên nhân: Switch giới hạn số 75 bị tuôn ren. Thực hiện: Đêm 26/12 Kiểm tra cào vận hành qua giới hạn số 75 bị dừng không chạy được do switch số 75 cần gạt bị tuôn ren. Tạm thời yêu cầu vận hành chỉnh lại toạ độ vùng cào đạm cho chạy sang vị trí khác sau đó tháo cần gạt switch về P.TCĐK bàn giao ca sau kiểm tra vật tư xử lý. Ngày 27/7 vệ sinh switch và gắn lại Kết quả: Đã gắn lại switch như ban đầu | M6: 1 | N6: 46018 | O6: 0.5 | P6: Đạt | Q6: Kíp IV | R6: Kíp IV Ca Ngày | T6: 40PI-2013 | U6: Lắp lại theo yêu cầu | V6: Nguyên nhân: Thực hiện theo yêu cầu VH Thực hiện: Kiểm tra thực hiện lắp PI theo yêu cầu sau khi VH thực hiện xong công việc Kết quả: Thiết bị đã lắp lại theo yêu cầu, bàn giao ĐVCQ.
A7: =A6+1 -> 6 | B7: 04PT-4504 | C7: N/A | D7: 6188/LVC | E7: AMONIA | F7: DK-AMLL | G7: giá trị sai (-4,7Kpa) so với điều kiện công nghệ 2-2.5Kpa | H7: SCĐX | I7: Nguyên nhân: Chưa tìm ra nguyên nhân gốc Thực hiện: Kiểm tra tại transmitter đo 04PT-4504ABC và vào bộ Mid Giá trị 3 transmitter gần đúng 2-2.5Kp. Dòng từ transmitter ouput tương ứng 5.2 mA. Đo sau bộ Mid vẫn 5.2 mA. Nhưng trên HMI PLC giá trị (-4,7Kpa) Hôm sau sẽ phối hợp cùng tổ PLC kiểm tra. Máy nén K04451 đang dừng, kiểm tra trend tình trạng này đã lâu. Kết quả: Vẫn đang sai HMI PLC và transmitter | M7: 1 | N7: 46018 | O7: 2 | P7: Chưa đạt | Q7: Kíp IV | R7: Kíp IV Ca Ngày | T7: 06VT-2123B | U7: VH báo giá trị độ rung cao 0.8-1.2 mm/s trong khi pump P06101B đang dừng | V7: Nguyên nhân: Barrier lỗi Thực hiện: Ngày 19/5 Kiểm tra đầu dò độ rung cao hơn so với các đầu dò khác 1,8xxmm/s mặc dù bơm đang dừng. Kiểm tra lịch sử đầu dò và barrier mới thay trong BDTT 2025, nhưng dây extension chưa thay, đánh giá trao đổi cùng planner và tổ chuyên môn lấy vật tư dây extension thay thế để loại trừ. Giá trị đã về 0,8xx mm/s sau khi thay thế. Ngày 20/5 Đánh giá chỉ còn barrier chưa thay khả năng barrier là cao. Nhận thay barier mới thay thế. Sau khi thay giá trị bộ rung về 0.06 mm/s. Kết quả: Thiết bị hoạt động bình thường.
A8: =A7+1 -> 7 | B8: W48001B | C8: N/A | D8: 6280/LVC | E8: SAN PHAM | F8: DK-SAN PHAM | G8: VH báo cân đối chứng trip liên tục mặc dù bao đủ ký ( tồn đọng) | H8: SCĐX | I8: Nguyên nhân: Vị trí sensor kết thúc báo chưa phù hợp . Thực hiện: Đêm 26/12 Kiểm tra cân đối chứng bao đi qua thì dừng, cân lại bao vẫn đủ ký. Calib lại cân, cân chỉnh đầu dò tuy nhiên vẫn dừng không có lý do. Tạm thời thay đầu cân W100 spare, cài đặt lại thông số đầu cân, zero và calib lại cân, đưa cân vào hoạt động. Ngày 27/12 Thay đầu cân từ line B NPK sang cài lại thông số đầu cân đóng bao được buổi sáng. Chiều lại lỗi tiếp, kiểm tra sensor, giá trị cài đều bình thường nhưng cân vẫn trip báo sai ký. Kéo bao đạm cân lại thì đúng ký. Vẫn chưa tìm ra nguyên nhân chuyển ca sau xử lý tiếp. ca Đ 27/12 Quan sát thấy cân đủ ký nhưng qua cân lại báo sai. Tiến hành điều chỉnh lại vị trí sensor kết thúc bao cho phù hợp. Theo dõi đến cuối ca, tần suất bao cân bị lỗi giảm nhiều khoảng trên 100 bao thì thỉnh thoảng bị 1 lần, chuyển ca ngày theo dõi thêm. Kết quả: Chuyển ca ngày theo dõi thêm, điều chỉnh nếu cần . | M8: 1 | N8: 46018 | O8: 2 | P8: Theo dõi | Q8: Kíp III | R8: Kíp III Ca Đêm | T8: 04PV-4251 CO2 Chiller | U8: Valve bị kẹt 0~5% | V8: Nguyên nhân: Travel lệch Thực hiện: Kiểm tra MV= 0~5% valve không di chuyển ty, output posit không có, tuy nhiên từ ~4.5% thì output posit có tác động và ti valve di chuyển. Dùng Hart kiểm tra thì travel lệch 5.1% ở 3.99mA. Tiến hành calib lại travel, valve hoạt động đúng, đáp ứng bình thường, bàn giao VH. Kết quả: Valve đáp ứng bình thường, bàn giao VH
A9: =A8+1 -> 8 | B9: 04PT-4504 | C9: N/A | D9: 6188/LVC | E9: AMONIA | F9: DK-AMLL | G9: giá trị sai (-4,7Kpa) so với điều kiện công nghệ 2-2.5Kpa (tồn động) | H9: SCĐX | I9: Nguyên nhân: Giá trị offset chưa phù hợp Thực hiện: Ngày 27/12 Kiểm tra tại transmitter đo 04PT-4504ABC và vào bộ Mid Giá trị 3 transmitter gần đúng 2-2.5Kp. Dòng từ transmitter ouput tương ứng 5.2 mA. Đo sau bộ Mid vẫn 5.2 mA. Nhưng trên HMI PLC giá trị (-4,7Kpa) Hôm sau sẽ phối hợp cùng tổ PLC kiểm tra. Máy nén K04451 đang dừng, kiểm tra trend tình trạng này đã lâu. Ngày 28/12 Kiểm tra phát hiện trên HIM đang cài offset (-17) phối hợp cùng Vận hành điều chỉnh offset tăng lên (-10) sau khi điều chỉnh giá trị trên HMI và transmitter tương đương nhau. Kết quả: Giá trị trên HMI và transmitter tương đương nhau. | M9: 1 | N9: 46019 | O9: 1 | P9: Đạt | Q9: Kíp III | R9: Kíp III Ca Đêm
A10: =A9+1 -> 9 | B10: W48001D | C10: N/A | D10: 6283/LVC | E10: SAN PHAM | F10: DK-SAN PHAM | G10: Cân hoạt động sai ký | H10: SCĐX | I10: Nguyên nhân: Thông số chưa phù hợp Thực hiện: Kiểm tra cân thiếu 150g. Tiến hành calibration với tải chuẩn Kết quả: Cân đã hoạt động đúng | M10: 1 | N10: 46019 | O10: 1 | P10: Đạt | Q10: Kíp III | R10: Kíp III Ca Đêm
A11: =A10+1 -> 10 | B11: 21PI-1234B | C11: N/A | D11: N/A | E11: UTILITY | F11: DK-HIEU CHUAN | G11: PI mất dịch glycerin | H11: SCĐX | I11: Nguyên nhân: PI mất dịch Thực hiện: Kiểm tra thiết bị mất dịch glycerin, tìm không phát hiện điểm rò, đã châm lại glycerin cho thiết bị. Kết quả: đã châm lại glycerin cho thiết bị. | M11: 1 | N11: 46019 | O11: 0.5 | P11: Đạt | Q11: Kíp III | R11: Kíp III Ca Đêm
A12: =A11+1 -> 11 | B12: W48001B | C12: N/A | D12: N/A | E12: SAN PHAM | F12: DK-SAN PHAM | G12: VH báo cân đối chứng trip liên tục mặc dù bao đủ ký ( tồn đọng) | H12: SCĐX | I12: Nguyên nhân: Vị trí sensor kết thúc báo chưa phù hợp . Thực hiện: Theo dõi từ đầu ca đến cuối ca thiết bị đã hoạt động ổn định Kết quả: Thiết bị đã hoạt động bình thường, bàn giao VH . | M12: 1 | N12: 46019 | O12: 1 | P12: Đạt | Q12: Kíp III | R12: Kíp III Ca Đêm
A13: =A12+1 -> 12 | B13: 06TT-1074 ( 06FJB1115) | C13: 2000018494 | D13: 6070/lvc | E13: UREA | F13: DK-NHIET DO | G13: Thông tin giao ca thiết bị lỗi barrier FF, các thiết bị I.O.P, C.N.F..., | H13: SCĐX | I13: Nguyên nhân: 06TT1074 bị lỗi Thực hiện: Qua kiểm tra barrier 06FJB1115( 06TT1074; 06TT1077; 06TT1078;06HV-1017; 06HV1011) thì lỗi ở 06TT1074, tiến hành cách ly thiết bị tại jbox 07FJB1115. Các thiết bị còn lại đã Normal, không ảnh hưởng công nghệ. Hiện tại đã hết tồn kho transmitter FF, đã khảo sát với VH về 06TT1081 ca ngày lấy 06TT1081 thay sang.Thiết bị 06TT1074 nằm trên đường ống cheo leo,móc dây an toàn lên thanh đà khi kiểm tra thiết bị . ( một số ảnh kèm theo ) Kết quả: Hiện tại đã cách ly thiết bị tại jbox, các thiết bị còn lại đã về trạng thái normal, ca ngày phối hợp VH chuyển transmitter khi có yêu cầu. | M13: 1 | N13: 46019 | O13: 1.5 | P13: Chưa đạt | Q13: Kíp III | R13: Kíp III Ca Đêm
A14: =A13+1 -> 13 | B14: 07ZSL-2607 | C14: N/A | D14: 6072/LVC | E14: UREA | F14: DK-SAN PHAM | G14: Switch không tác dộng | H14: SCĐX | I14: Nguyên nhân: Switch bị lệch Thực hiện: Chỉnh lại đúng vị trí Kết quả: Thiết bị đã hoạt động bình thường, bàn giao VH | M14: 1 | N14: 46020 | O14: 0.5 | P14: Đạt | Q14: Kíp I | R14: Kíp I Ca Ngày
A15: =A14+1 -> 14 | B15: 07ZSL-2601 đến 07ZSL-2609 | C15: N/A | D15: 6072/LVC | E15: UREA | F15: DK-SAN PHAM | G15: Làm gọn lại dây tín hiệu | H15: SCĐX | I15: Nguyên nhân: Dây tín hiệu chưa rút gọn Thực hiện: lấy dây rút rút gọn lại Kết quả: Thiết bị đã được làm gọn, bàn giao VH | M15: 1 | N15: 46020 | O15: 1.5 | P15: Đạt | Q15: Kíp I | R15: Kíp I Ca Ngày
A16: =A15+1 -> 15 | B16: 07SSL-2652C | C16: N/A | D16: 6072/LVC | E16: UREA | F16: DK-SAN PHAM | G16: Tín hiệu chập chờn lúc mức 0, lúc mức 1 | H16: SCĐX | I16: Nguyên nhân: Dây tín hiệu có dấu hiệu lão hóa Thực hiện: Bypass trên DCS, thay qua dây sapre Kết quả: Thiết bị đôi lúc vẫn còn chập chờn, khi sàn rung chạy thì không bị chập chờn, đang bypass trên DCS, bàn giao VH theo dõi tiếp đến ca ngày mai đánh giá thay board sensor | M16: 1 | N16: 46020 | O16: 1 | P16: Chưa Đạt | Q16: Kíp I | R16: Kíp I Ca Ngày
A17: =A16+1 -> 16 | B17: 06TT-1074 | C17: 2000018494 | D17: 6072/LVC | E17: UREA | F17: DK-NHIET DO | G17: Xử lý lỗi thiết bị báo CNF | H17: SCĐX | I17: Nguyên nhân: thiết bi hỏng báo CNF . Thực hiện: Tháo 06TT1081 thay thế cho 06TT1074 Kết quả: Thiết bị đã hoạt động bình thường, bàn giao VH . | M17: 1 | N17: 46020 | O17: 2 | P17: Đạt | Q17: Kíp I | R17: Kíp I Ca Ngày
A18: =A17+1 -> 17 | B18: 06PI-0576 06PI-0577 | C18: N/A | D18: 6072/LVC | E18: UREA | F18: DK-HIEU CHUAN | G18: Lắp lại PI sau khi hiệu chuẩn xong | H18: SCĐX | I18: Nguyên nhân: Lắp lại thiết bị sau hiệu chuẩn Thực hiện: lắp lại thiết bị Kết quả: Thiết bị đã hoạt động bình thường, bàn giao VH | M18: 1 | N18: 46020 | O18: 1 | P18: Đạt | Q18: Kíp I | R18: Kíp I Ca Ngày
A19: =A18+1 -> 18 | B19: 06PI-0565 | C19: N/A | D19: 6072/LVC | E19: UREA | F19: DK-HIEU CHUAN | G19: Rò dầu khớp nối | H19: SCĐX | I19: Nguyên nhân: chưa rõ nguyên nhân Thực hiện: Siết rò Kết quả: Thiết bị đã hết rò, bàn giao VH . | M19: 1 | N19: 46020 | O19: 0.5 | P19: Đạt | Q19: Kíp I | R19: Kíp I Ca Ngày
A20: =A19+1 -> 19 | B20: 06TT-1081 | C20: N/A | D20: 6072/LVC | E20: UREA | F20: DK-NHIET DO | G20: Tháo transmitter thay cho 06TT1074 | H20: SCĐX | I20: Nguyên nhân: Thực hiện theo yêu cầu VH Thực hiện: Tháo transmitter lắp cho vị trí 06TT1074. Kết quả: Thiết bị đã được cách ly và tháo transmitter. Chờ vật tu thay thế | M20: 1 | N20: 46020 | O20: 0.5 | P20: Chưa Đạt | Q20: Kíp I | R20: Kíp I Ca Ngày
A21: =A20+1 -> 20 | B21: 06PI-0571 06PI-0573 | C21: N/A | D21: 6072/LVC | E21: UREA | F21: DK-HIEU CHUAN | G21: Thiết bị đo sai (giao ca) | H21: SCĐX | I21: Nguyên nhân: Gãy kim Thực hiện: Tháo đồng hồ áp suất bàn giao ca sau chuyển Tổ HCH sửa chữa Kết quả: Đồng hồ đã tháo về P.TCĐK | M21: 1 | N21: 46020 | O21: 0.5 | P21: Chưa Đạt | Q21: Kíp II | R21: Kíp II Ca Đêm
A22: =A21+1 -> 21 | B22: 06TI-0520 | C22: N/A | D22: 6072/LVC | E22: UREA | F22: DK-HIEU CHUAN | G22: Đồng hồ đo nhiệt sai nhiệt độ | H22: SCĐX | I22: Nguyên nhân: Chưa rõ nguyên nhân Thực hiện: Tháo đồng hồ nhiệt bàn giao ca sau chuyển Tổ HCH sửa chữa Kết quả: Đồng hồ đã tháo về P.TCĐK | M22: 1 | N22: 46020 | O22: 0.5 | P22: Chưa Đạt | Q22: Kíp II | R22: Kíp II Ca Đêm
A23: =A22+1 -> 22 | B23: W48001E | C23: N/A | D23: 06290/LVC | E23: SAN PHAM | F23: DK-SAN PHAM | G23: VH báo cân sai so với cân bàn 200gram | H23: SCĐX | I23: Nguyên nhân: Cân đối chứng sai ký. Thực hiện: Vệ sinh sau đó calib với tải chuẩn, đưa cân vào hoạt động. Kết quả: Cân đối chứng đã hoạt động bình thường, bàn giao VH . | M23: 1 | N23: 46020 | O23: 1 | P23: Đạt | Q23: Kíp II | R23: Kíp II Ca Đêm
A24: =A23+1 -> 23 | B24: Z08103 | C24: N/A | D24: 6072/LVC | E24: NPK | F24: DK-NPK | G24: VH báo gàu tải lỗi tốc độ | H24: SCĐX | I24: Nguyên nhân: Nghi ngờ đầu dò lỗi Thực hiện: Gàu tải không chạy được, kiểm tra vệ sinh đầu dò tốc đưa gàu tải vào hoạt động. Kết quả: Gàu tải đã hoạt động bình thường, bàn giao VH . | M24: 1 | N24: 46020 | O24: 1 | P24: Đạt | Q24: Kíp II | R24: Kíp II Ca Đêm
A25: =A24+1 -> 24 | B25: W48001A | C25: N/A | D25: 6294/LVC | E25: SAN PHAM | F25: DK-SAN PHAM | G25: Cân B sai ký | H25: SCĐX | I25: Nguyên nhân: Cân sai chưa rõ nguyên nhân Thực hiện: Kiểm tra phát hiện cân đóng đủ 50kg nhưng sai so với cân bàn, tiến hành calibrate lại cân, sau khi calibrate xong cân hoạt động ổn định, bàn giao ĐVVH Kết quả: Thiết bị hoạt động bình thường, bàn giao ĐVVH | M25: 1 | N25: 46021 | O25: 1 | P25: Đạt | Q25: Kíp I | R25: Kíp I Ca Ngày
A26: =A25+1 -> 25 | B26: W48001F | C26: N/A | D26: 6294/LVC | E26: SAN PHAM | F26: DK-SAN PHAM | G26: Máy in line F lỗi ngắt cao áp | H26: SCĐX | I26: Nguyên nhân: Đầu in bị dơ Thực hiện: Kiểm tr phát hiện máy in báo lỗi ngắt cao áp, tiến hành vệ sinh đầu in bàn giao ĐVVH Kết quả: Thiết bị hoạt động bình thường, bàn giao ĐVVH | M26: 1 | N26: 46021 | O26: 1 | P26: Đạt | Q26: Kíp I | R26: Kíp I Ca Ngày
A27: =A26+1 -> 26 | B27: 04TT-2500 | C27: BSS | D27: 6207/LVC | E27: AMONIA | F27: DK-NHIET DO | G27: Nhiệt độ giảm bất thường gây kích hoạt interlock I211 | H27: SCĐX | I27: Nguyên nhân: Chưa rõ nguyên nhân gốc Thực hiện: - Kiểm tra lại hệ thống phát hiện nhiệt độ giảm đột ngột về dưới 175degC gây kích hoạt interlock I211 gây đóng van 04TV2112. - Thực hiện MOS tín hiệu trip mức thấp để ĐVVVH reset lại interlock mở van lại. - Sau khi công nghệ ổn định tiến hành kiểm tra đo đạc 2 sensor (TC - K) không phát hiện bất thường, nhiệt độ 2 sensor giống nhau tương đương nhiệt độ vận hành. - Trao đổi với TCNM và ĐVCQ đánh giá sơ bộ các nguyên nhân có thể gây trip. Thống nhất thay thế 04TT2500 để loại trừ và theo dõi. - Sau khi thay thế xong giá trị nhiệt độ hiển thị ổn định bàn giao ĐVVH theo dõi trong 24h tiếp theo, song song đó đưa transmitter cũ (Yokogawa YTA610) về phòng Mô hình để kiểm tra lại thiết bị Kết quả: Thiết bị hoạt động bình thường sau khi thay thế, bàn giao ĐVVH theo dõi, vẫn giữ MOS trong 24h để đánh giá | M27: 1 | N27: 46021 | O27: 5 | P27: Đạt | Q27: Kíp I | R27: Kíp I Ca Ngày
A28: =A27+1 -> 27 | B28: 06PI-0571 | C28: N/A | D28: 5988/LVC | E28: UREA | F28: DK-HIEU CHUAN | G28: Lắp lại PI | H28: SCĐX | I28: Nguyên nhân:PI gãy kim Thực hiện: Ca đêm: 29/12/2025: Tháo đồng hồ áp suất bàn giao ca sau chuyển Tổ HCH sửa chữa Ca ngày 30/12/2025: Thực hiện lắp lại PI sau khi thay thế kim đồng hồ xong Kết quả: Thiết bị hoạt động bình thường, bàn giao ĐVVH | M28: 1 | N28: 46021 | O28: 1 | P28: Đạt | Q28: Kíp I | R28: Kíp I Ca Ngày
A29: =A28+1 -> 28 | B29: L08201C | C29: N/A | D29: 5824/LVC | E29: NPK | F29: DK-NPK | G29: Cân sai | H29: SCĐX | I29: Nguyên nhân: Hỏng đầu cân Thực hiện: Kiểm tra phát hiện hỏng đầu cân B, tiến hành sử dụng đầu cân cũ của line B đã tháo sang thay thế bàn giao ĐVVH chạy lại cân Kết quả: Thiết bị hoạt động bình thường, bàn giao ĐVVH | M29: 1 | N29: 46021 | O29: 1 | P29: Đạt | Q29: Kíp I | R29: Kíp I Ca Ngày
... A50: =A49+1 -> 49 | B50: 04AE-2077 | C50: N/A | D50: 6225/lvc | E50: AMONIA | F50: DK-PHAN TICH | G50: Thiết bi vent lớn, ảnh hưởng thiết bị xung quanh | H50: SCĐX | I50: Nguyên nhân: Valve vent mở full, các fitting bị hỏng Nội dung thực hiện: Kiểm tra valve vent khí đang mở full, rò đầu ra của bộ lọc đến bình ngưng, rò đầu ra output. Do fitting bị hỏng tiến hành thay thế fitting mới, thay thế ống impulse line khắc phục rò. Phối hợp VH điều chỉnh valve vent phù hợp. Thiết bị đã được điều chỉnh valve vent phù hợp, thay thế fitting và impulse line mới khắc phục rò Kết quả: Thiết bị đã được điều chỉnh valve vent phù hợp, thay thế fitting và impulse line mới khắc phục rò | M50: 1 | N50: 46023 | O50: 4 | P50: Đạt | Q50: Kíp III | R50: Kíp III Ca Ngày
A51: =A50+1 -> 50 | B51: L48001A | C51: N/A | D51: 6298/lvc | E51: SAN PHAM | F51: DK-SAN PHAM | G51: Cân A line A bị giao động, dư ký. | H51: SCĐX | I51: Nguyên nhân: Chưa rõ nguyên nhân. Nội dung thực hiện: Kiểm tra dây căng thùng cân 2 bên trùng, lỏng. Cửa xả đóng mở mạnh, thông số cửa tinh chưa phù hợp. Tiến hành điều chỉnh dây dai thung cân, cửa xả và thông số cửa tinh phù hợp. Cân hoạt động bình thường, bàn giao VH Kết quả: Cân hoạt động bình thường, bàn giao VH | M51: 1 | N51: 46023 | O51: 1,5 | P51: Đạt | Q51: Kíp III | R51: Kíp III Ca Ngày
A52: =A51+1 -> 51 | B52: 04PDT-2511A/B | C52: N/A | D52: 6226/LVC | E52: AMONIA | F52: DK-AMLL | G52: Cần cô lập hoàn toàn công nghệ để X.Amo tháo thiết bị sửa chữa | H52: SCĐX | I52: Nguyên nhân: Đảm bảo công nghệ hoàn toàn kín Nội dung thực hiện: Vận hành cô lập van block, ĐK cô lập 2 van isolate của transmitter Kết quả: 2 van isolate đã được cô lập | M52: 1 | N52: 46023 | O52: 1 | P52: Đạt | Q52: Kíp IV | R52: Kíp IV Ca Đêm
A53: =A52+1 -> 52 | B53: L08201B | C53: N/A | D53: 5829/LVC | E53: NPK | F53: DK-DCS | G53: Cân thiếu ký | H53: SCĐX | I53: Nguyên nhân: Thông số chưa phù hợp Nội dung thực hiện: Điều chỉnh thông số cửa tô từ 250 về 240.Của tinh từ 100 về 90. Theo dõi cân đã hoạt động đúng. Kết quả: Cân hoạt động đúng | M53: 1 | N53: 46023 | O53: 1 | P53: Đạt | Q53: Kíp IV | R53: Kíp IV Ca Đêm
A54: =A53+1 -> 53 | B54: 20AT-2004A/B/C | C54: N/A | D54: 2251/LVC | E54: UTILITY | F54: DK-PHAN TICH | G54: Thiết bị đo sai | H54: SCĐX | I54: Nguyên nhân: Chưa tìm được nguyên nhân Nội dung thực hiện: Giá trị hiển thị 0. Kiểm tra điều kiện lấy mẫu, dịch referance còn đủ. Tiến hành auto clean nhưng thiết bị vẫn chưa có giá trị. Chuyển ca ngày kiểm tra Kết quả: Thiết bị còn sai | M54: 1 | N54: 46023 | O54: 1 | P54: Chưa đạt | Q54: Kíp IV | R54: Kíp IV Ca Đêm
A55: =A54+1 -> 54 | B55: 20AT-2004A/B/C | C55: N/A | D55: N/A | E55: UTILITY | F55: DK-PHAN TICH | G55: Thiết bị đo sai ( giao ca) | H55: SCĐX | I55: Nguyên nhân: Chưa tìm được nguyên nhân Nội dung thực hiện: Giá trị hiển thị 0. Kiểm tra điều kiện lấy mẫu, dịch referance còn đủ. Tiến hành auto clean nhưng thiết bị vẫn chưa có giá trị. 2/6 Thực hiện kiểm tra dòng vào các stream chưa phát hiện bất thường, Manual Clean tuy nhiên giá trị vẫn ~ 0ppm, chuyển ca sau theo dõi xử lý thêm. Kết quả: Thiết bị còn sai | M55: 1 | N55: 46024 | O55: 2 | P55: Theo dõi | Q55: Kíp II | R55: Kíp II Ca Ngày
A56: =A55+1 -> 55 | B56: Hệ cân 5kg NPK | C56: 2000018530 | D56: 5831/lvc | E56: NPK | F56: DK-NPK | G56: Thiết bị bị hỏng cóc đạp | H56: SCĐX | I56: Nguyên nhân: Thiết bị lão hóa, ăn mòn làm gãy bàn đạp Nội dung thực hiện: Kiểm tra, thiết bị lão hóa, ăn mòn làm gãy bàn đạp. HC hỗ trợ cung cấp thông tin vật tư, tiến hành nhận vật tư mới thay thế thiết bị hỏng, test cùng vận hành sau khi thay thế, thiết bị hoạt động đúng chức năng, bàn giao VH Kết quả: Thiết bị đã được thay thế, động đúng chức năng, bàn giao VH | M56: 1 | N56: 46024 | O56: 2 | P56: Đạt | Q56: Kíp II | R56: Kíp II Ca Ngày
A57: =A56+1 -> 56 | B57: 08TV-0034 | C57: 2000018532 | D57: 05725/lvc | E57: NPK | F57: DK-VALVE | G57: Thiết bị không điều khiển được | H57: SCĐX | I57: Nguyên nhân: Hỏng solenoid Nội dung thực hiện: Kiểm tra, phát hiện thiết bị bị hỏng solenoid nên không có khí cấp cho posit. Tiến hành sang kho nhận vật tư và thay thế solenoid đưa valve vào hoạt động bình thường, troke test hành trình valve đáp ứng bình thường, bàn giao VH Kết quả: Valve hoạt động bình thường, bàn giao VH | M57: 1 | N57: 46024 | O57: 1 | P57: Đạt | Q57: Kíp II | R57: Kíp II Ca Ngày
A58: =A57+1 -> 57 | B58: Thiết bị đo nhiệt độ dùng pin | C58: N/A | D58: 6228/lvc | E58: AMONIA | F58: DK-HIEU CHUAN | G58: Theo yêu cầu VH lắp thiết bị đo nhiệt độ tại field cho VH theo dõi chuẩn bi thay xúc tác | H58: SCĐX | I58: Nguyên nhân: Theo yêu cầu VH. Nội dung thực hiện: Kiểm tra, phối hợp tổ HC kiểm tra thông tin thiết bị, tiến hành mang thiết bị ra field lắp theo yêu cầu VH.(hạng mục đã từng lắp trước đây mỗi khi VH thay xúc tác) Kết quả:Hạng mục đã được phối hợp theo yêu cầu. | M58: 1 | N58: 46024 | O58: 1.5 | P58: Đạt | Q58: Kíp II | R58: Kíp II Ca Ngày
A59: =A58+1 -> 58 | B59: 06TT-1068 | C59: 2000018531 | D59: 6000/lvc | E59: UREA | F59: DK-NHIET DO | G59: Thiết bị đo nhiệt độ dao động , Alarm C.N.F | H59: SCĐX | I59: Nguyên nhân: Hỏng transmitter Nội dung thực hiện: Kiểm tra, nguồn 13Vdc, range ( 0~300) degC, TC K , TH400. sensor 1~ 2~ 158degC. Thiết bị C.N.F. Looptest không tác dụng. Nghi ngờ transmiter hỏng, hiện tại đã hết tồn kho transmitter FF. Kết quả: Thiết bị Alarm CN.F. Chờ thay thế transmitter Kiến nghị: Planner bổ sung vật tư thay thế. | M59: 1 | N59: 46024 | O59: 1.5 | P59: Chưa đạt | Q59: Kíp II | R59: Kíp II Ca Ngày
A60: =A59+1 -> 59 | B60: 04PI-2104B | C60: N/A | D60: 6229/lvc | E60: AMONIA | F60: DK-HIEU CHUAN | G60: Xoay mặt đồng hồ hướng về sàn thao tác để dễ ghi nhận thông số hằng ca, và khi thao tác đổi bơm dễ quan sát được áp suất (PM hỗ trợ AM ) | H60: SCĐX | I60: Nguyên nhân: Hạng mục PM hỗ trợ AM Nội dung thực hiện: Xoay mặt đồng hồ hướng về sàn thao tác để dễ ghi nhận thông số hằng ca, và khi thao tác đổi bơm dễ quan sát được áp suất Kết quả: Hạng mục đã được xử lý xong. | M60: 1 | N60: 46024 | O60: 1 | P60: Đạt | Q60: Kíp II | R60: Kíp II Ca Ngày
...

Sheet BC_LĐNM
A1: STT | B1: HANG_MUC | C1: THONG_TIN_TU_VH | D1: TUAN | E1: KQ | F1: NOI_DUNG_THUC_HIEN | K1: =COUNTIF(J:J,"*") -> 3 | L1: HM chưa đạt trong tuần
A2: 1 | B2: 06PXT-0250B | C2: Thiết bị đo áp bị dao động cao ( tồn đọng) | D2: 21 | E2: Đạt | F2: Nguyên nhân: Bộ D/A lỗi. Thực hiện: 14/5 :Kiểm tra giá trị đo áp có xung tăng giảm liên tục. Tiến hành MOS giá trị (HH&LL) trên ESD.Kiểm tra tại site vent không phát hiện bất thường. 15/5 PV dao động mạnh, kiểm tra bộ D/A dao động, tiến hành nhận vật tư, test report transmitter mới. 16/5: Thay mới transmitter, loop test , report cùng VH, thiết bị hoạt động bình thường, bàn giao VH Kết quả: Thiết bị hoạt động bình thường, bàn giao VH, bỏ bypass tín hiệu LL, HH theo yêu cầu vận hành sau khi theo dõi thấy ổn. Thiết bị hoạt động bình thường, bàn giao VH | G2: DK-AMLL | J2: {=_xlfn._xlws.FILTER(B2:B275, _xlfn.XLOOKUP(B2:B275, B2:B275, E2:E275, ,0,-1)="Chưa đạt")} -> Camera 44/45/46/47 | K2: {=_xlfn._xlws.FILTER(C2:C275, _xlfn.XLOOKUP(B2:B275, B2:B275, E2:E275,,0,-1)="Chưa đạt")} -> An Toàn báoCamera 44/45/46/47 khu vực phía sau nhà đóng bao NPK | L2: {=_xlfn.UNIQUE(_xlfn._xlws.FILTER(F2:F275, _xlfn.XLOOKUP(B2:B275, B2:B275, E2:E275,,0,-1)="Chưa đạt"))} -> Nguyên nhân : Không cón tín hiệu truyền thông quang. Thực hiện: Kiểm tra các tủ box đấu nối thì phát hiện không có tín hiệu truyền thông quang, chưa rõ nguyên nhân. An Toàn đã thông tin nhà thầu kiểm tra lại Kết quả: Hiện camera chưa lên hình, An Toàn đã thông tin nhà thầu kiểm tra lại .
